Workbook
Name _B6: #N/A
Name _B6: #N/A
Name _B6: #REF!
Name _B7: #N/A
Name _B7: #N/A
Name _B7: #REF!
Name _C10: #N/A
Name _C10: #N/A
Name _C10: #REF!
Name _C11: #N/A
Name _C11: #N/A
Name _C11: #REF!
Name _C12: #N/A
Name _C12: #N/A
Name _C12: #REF!
Name _C8: #N/A
Name _C8: #N/A
Name _C8: #REF!
Name _C9: #N/A
Name _C9: #N/A
Name _C9: #REF!
Name _D10: #N/A
Name _D10: #N/A
Name _D10: #REF!
Name _D11: #N/A
Name _D11: #N/A
Name _D11: #REF!
Name _D12: #N/A
Name _D12: #N/A
Name _D12: #REF!
Name _D13: #N/A
Name _D13: #N/A
Name _D13: #REF!
Name _D14: #N/A
Name _D14: #N/A
Name _D14: #REF!
Name _D15: #N/A
Name _D15: #N/A
Name _D15: #REF!
Name _D16: #N/A
Name _D16: #N/A
Name _D16: #REF!
Name _D17: #N/A
Name _D17: #N/A
Name _D17: #REF!
Name _D18: #N/A
Name _D18: #N/A
Name _D18: #REF!
Name formula: #N/A
Name iii: #REF!
Name PAL: #N/A
Name Paver: #N/A
Name PLANILHA: #REF!
Name tubo: #REF!

Sheet MENU

Sheet 1 Areia
A2: COMPOSIÇÃO GRANULOMÉTRICA DE UM AGREGADO MIÚDO | H2: Data:
A3: Peneira com abertura de malha (ABNT NBR NM ISO 3310-1) | B3: Areia regular | G3: %, em massa, retida acumulada
G4: Limites Inf. | I4: Limites Sup.
B5: Ensaio 1 | C5: Ensaio 2 | D5: Média | E5: Retido (%) | F5: Acum. (%) | G5: Zona util | H5: Zona ótima | I5: Zona ótima | J5: Zona util
A6: 9.5 | D6: =(B6+C6)/2 -> 0 | E6: =D6/$D$16*100 -> 0 | F6: =E6 -> 0 | G6: 0 | H6: 0 | I6: 0 | J6: 0
A7: 6.3 | D7: =(B7+C7)/2 -> 0 | E7: =D7/$D$16*100 -> 0 | F7: =F6+E7 -> 0 | G7: 0 | H7: 0 | I7: 0 | J7: 7
A8: 4.8 | B8: 6 | C8: 9 | D8: =(B8+C8)/2 -> 7.5 | E8: =D8/$D$16*100 -> 1.2931034 | F8: =F7+E8 -> 1.2931034 | G8: 0 | H8: 0 | I8: 5 | J8: 10
A9: 2.4 | B9: 52 | C9: 54 | D9: =(B9+C9)/2 -> 53 | E9: =D9/$D$16*100 -> 9.137931 | F9: =F8+E9 -> 10.431034 | G9: 0 | H9: 10 | I9: 20 | J9: 25
A10: 1.2 | B10: 98 | C10: 105 | D10: =(B10+C10)/2 -> 101.5 | E10: =D10/$D$16*100 -> 17.5 | F10: =F9+E10 -> 27.931034 | G10: 5 | H10: 20 | I10: 30 | J10: 50
A11: 0.6 | B11: 107 | C11: 99 | D11: =(B11+C11)/2 -> 103 | E11: =D11/$D$16*100 -> 17.758621 | F11: =F10+E11 -> 45.689655 | G11: 15 | H11: 35 | I11: 55 | J11: 70
A12: 0.3 | B12: 215 | C12: 203 | D12: =(B12+C12)/2 -> 209 | E12: =D12/$D$16*100 -> 36.034483 | F12: =F11+E12 -> 81.724138 | G12: 50 | H12: 65 | I12: 85 | J12: 95
A13: 0.15 | B13: 86 | C13: 103 | D13: =(B13+C13)/2 -> 94.5 | E13: =D13/$D$16*100 -> 16.293103 | F13: =F12+E13 -> 98.017241 | G13: 85 | H13: 90 | I13: 95 | J13: 100
A14: 0.075 | B14: 13 | C14: 6 | D14: =(B14+C14)/2 -> 9.5 | E14: =D14/$D$16*100 -> 1.637931 | F14: =F13+E14 -> 99.655172 | G14: 100 | H14: 100 | I14: 100 | J14: 100
A15: 0.0375 | B15: 3 | C15: 1 | D15: =(B15+C15)/2 -> 2 | E15: =D15/$D$16*100 -> 0.34482759 | F15: =F14+E15 -> 100 | G15: 100 | H15: 100 | I15: 100 | J15: 100
B16: =SUM(B6:B15) -> 580 | C16: =SUM(C6:C15) -> 580 | D16: =SUM(D6:D15) -> 580 | E16: =SUM(E6:E15) -> 100 | G16: 100 | H16: 100 | I16: 100 | J16: 100
A17: Mód Finura | B17: =(F6+F8+F9+F10+F11+F12+F13)/100 -> 2.6508621 | G17: =(G6+G8+G9+G10+G11+G12+G13)/100 -> 1.55 | H17: =(H6+H8+H9+H10+H11+H12+H13)/100 -> 2.2 | I17: =(I6+I8+I9+I10+I11+I12+I13)/100 -> 2.9 | J17: =(J6+J8+J9+J10+J11+J12+J13)/100 -> 3.5
L32: ⁭
M41: ⁭

Sheet Mescla 2 Areias
A2: COMPOSIÇÃO IDEAL DOS AGREGADOS MIÚDOS | P2: Data:
A3: Peneira com abertura de malha (ABNT NBR NM ISO 3310-1) | B3: Areia fina | H3: Areia Regular | N3: %, em massa, retida acumulada
N4: Mescla | O4: Limites Inf. | Q4: Limites Sup.
B5: Ensaio 1 | C5: Ensaio 2 | D5: Média | E5: Retido (%) | F5: Acum. (%) | G5: Prop. (%) | H5: Ensaio 1 | I5: Ensaio 2 | J5: Média | K5: Retido (%) | L5: Acum. (%) | M5: Prop. (%) | O5: Zona util | P5: Zona ótima | Q5: Zona ótima | R5: Zona util
A6: 9.5 | D6: =(B6+C6)/2 -> 0 | E6: =D6/$D$16*100 -> 0 | F6: =E6 -> 0 | G6: =(G$18*F6)/100 -> 0 | J6: =(H6+I6)/2 -> 0 | K6: =J6/$J$16*100 -> 0 | L6: =K6 -> 0 | M6: =(M$18*L6)/100 -> 0 | N6: =(G6+M6) -> 0 | O6: 0 | P6: 0 | Q6: 0 | R6: 0
A7: 6.3 | D7: =(B7+C7)/2 -> 0 | E7: =D7/$D$16*100 -> 0 | F7: =F6+E7 -> 0 | G7: =(G$18*F7)/100 -> 0 | J7: =(H7+I7)/2 -> 0 | K7: =J7/$J$16*100 -> 0 | L7: =L6+K7 -> 0 | M7: =(M$18*L7)/100 -> 0 | N7: =(G7+M7) -> 0 | O7: 0 | P7: 0 | Q7: 0 | R7: 7
A8: 4.8 | D8: =(B8+C8)/2 -> 0 | E8: =D8/$D$16*100 -> 0 | F8: =F7+E8 -> 0 | G8: =(G$18*F8)/100 -> 0 | H8: 6 | I8: 9 | J8: =(H8+I8)/2 -> 7.5 | K8: =J8/$J$16*100 -> 1.2931034 | L8: =L7+K8 -> 1.2931034 | M8: =(M$18*L8)/100 -> 0.96982759 | N8: =(G8+M8) -> 0.96982759 | O8: 0 | P8: 0 | Q8: 5 | R8: 10
A9: 2.4 | D9: =(B9+C9)/2 -> 0 | E9: =D9/$D$16*100 -> 0 | F9: =F8+E9 -> 0 | G9: =(G$18*F9)/100 -> 0 | H9: 52 | I9: 54 | J9: =(H9+I9)/2 -> 53 | K9: =J9/$J$16*100 -> 9.137931 | L9: =L8+K9 -> 10.431034 | M9: =(M$18*L9)/100 -> 7.8232759 | N9: =(G9+M9) -> 7.8232759 | O9: 0 | P9: 10 | Q9: 20 | R9: 25
A10: 1.2 | D10: =(B10+C10)/2 -> 0 | E10: =D10/$D$16*100 -> 0 | F10: =F9+E10 -> 0 | G10: =(G$18*F10)/100 -> 0 | H10: 98 | I10: 105 | J10: =(H10+I10)/2 -> 101.5 | K10: =J10/$J$16*100 -> 17.5 | L10: =L9+K10 -> 27.931034 | M10: =(M$18*L10)/100 -> 20.948276 | N10: =(G10+M10) -> 20.948276 | O10: 5 | P10: 20 | Q10: 30 | R10: 50
A11: 0.6 | D11: =(B11+C11)/2 -> 0 | E11: =D11/$D$16*100 -> 0 | F11: =F10+E11 -> 0 | G11: =(G$18*F11)/100 -> 0 | H11: 107 | I11: 99 | J11: =(H11+I11)/2 -> 103 | K11: =J11/$J$16*100 -> 17.758621 | L11: =L10+K11 -> 45.689655 | M11: =(M$18*L11)/100 -> 34.267241 | N11: =(G11+M11) -> 34.267241 | O11: 15 | P11: 35 | Q11: 55 | R11: 70
A12: 0.3 | B12: 15 | C12: 11 | D12: =(B12+C12)/2 -> 13 | E12: =D12/$D$16*100 -> 2.3111111 | F12: =F11+E12 -> 2.3111111 | G12: =(G$18*F12)/100 -> 0.57777778 | H12: 215 | I12: 203 | J12: =(H12+I12)/2 -> 209 | K12: =J12/$J$16*100 -> 36.034483 | L12: =L11+K12 -> 81.724138 | M12: =(M$18*L12)/100 -> 61.293103 | N12: =(G12+M12) -> 61.870881 | O12: 50 | P12: 65 | Q12: 85 | R12: 95
A13: 0.15 | B13: 394 | C13: 422 | D13: =(B13+C13)/2 -> 408 | E13: =D13/$D$16*100 -> 72.533333 | F13: =F12+E13 -> 74.844444 | G13: =(G$18*F13)/100 -> 18.711111 | H13: 86 | I13: 103 | J13: =(H13+I13)/2 -> 94.5 | K13: =J13/$J$16*100 -> 16.293103 | L13: =L12+K13 -> 98.017241 | M13: =(M$18*L13)/100 -> 73.512931 | N13: =(G13+M13) -> 92.224042 | O13: 85 | P13: 90 | Q13: 95 | R13: 100
A14: 0.075 | B14: 150 | C14: 131 | D14: =(B14+C14)/2 -> 140.5 | E14: =D14/$D$16*100 -> 24.977778 | F14: =F13+E14 -> 99.822222 | G14: =(G$18*F14)/100 -> 24.955556 | H14: 13 | I14: 6 | J14: =(H14+I14)/2 -> 9.5 | K14: =J14/$J$16*100 -> 1.637931 | L14: =L13+K14 -> 99.655172 | M14: =(M$18*L14)/100 -> 74.741379 | N14: =(G14+M14) -> 99.696935 | O14: 100 | P14: 100 | Q14: 100 | R14: 100
A15: 0.0375 | B15: 1 | C15: 1 | D15: =(B15+C15)/2 -> 1 | E15: =D15/$D$16*100 -> 0.17777778 | F15: =F14+E15 -> 100 | G15: =(G$18*F15)/100 -> 25 | H15: 3 | I15: 1 | J15: =(H15+I15)/2 -> 2 | K15: =J15/$J$16*100 -> 0.34482759 | L15: =L14+K15 -> 100 | M15: =(M$18*L15)/100 -> 75 | N15: =(G15+M15) -> 100 | O15: 100 | P15: 100 | Q15: 100 | R15: 100
A16: (%) | B16: =SUM(B6:B15) -> 560 | C16: =SUM(C6:C15) -> 565 | D16: =SUM(D6:D15) -> 562.5 | E16: =SUM(E6:E15) -> 100 | H16: =SUM(H6:H15) -> 580 | I16: =SUM(I6:I15) -> 580 | J16: =SUM(J6:J15) -> 580 | K16: =SUM(K6:K15) -> 100 | N16: =(G18+M18)/100 -> 1
A17: Mód Finura | B17: =(F6+F8+F9+F10+F11+F12+F13)/100 -> 0.77155556 | H17: =(L6+L8+L9+L10+L11+L12+L13)/100 -> 2.6508621 | N17: =(N6+N8+N9+N10+N11+N12+N13)/100 -> 2.1810354 | O17: =(O6+O8+O9+O10+O11+O12+O13)/100 -> 1.55 | P17: =(P6+P8+P9+P10+P11+P12+P13)/100 -> 2.2 | Q17: =(Q6+Q8+Q9+Q10+Q11+Q12+Q13)/100 -> 2.9 | R17: =(R6+R8+R9+R10+R11+R12+R13)/100 -> 3.5
B18: Teor na mistura de areia fina | G18: 25 | H18: Teor na mistura de areia regular | M18: =100-G18 -> 75
T34: ⁭
U43: ⁭

Sheet Mescla 3 Areias
A2: COMPOSIÇÃO IDEAL DOS AGREGADOS MIÚDOS | V2: Data:
A3: Peneira com abertura de malha (ABNT NBR NM ISO 3310-1) | B3: Areia fina | H3: Areia Regular | N3: Areia Grossa | T3: %, em massa, retida acumulada
T4: Mescla | U4: Limites Inf. | W4: Limites Sup.
B5: Ensaio 1 | C5: Ensaio 2 | D5: Média | E5: Retido (%) | F5: Acum. (%) | G5: Prop. (%) | H5: Ensaio 1 | I5: Ensaio 2 | J5: Média | K5: Retido (%) | L5: Acum. (%) | M5: Prop. (%) | N5: Ensaio 1 | O5: Ensaio 2 | P5: Média | Q5: Retido (%) | R5: Acum. (%) | S5: Prop. (%) | U5: Zona util | V5: Zona ótima | W5: Zona ótima | X5: Zona util
A6: 9.5 | D6: =(B6+C6)/2 -> 0 | E6: =D6/$D$16*100 -> 0 | F6: =E6 -> 0 | G6: =(G$18*F6)/100 -> 0 | J6: =(H6+I6)/2 -> 0 | K6: =J6/$J$16*100 -> 0 | L6: =K6 -> 0 | M6: =(M$18*L6)/100 -> 0 | N6: 12 | O6: 17 | P6: =(N6+O6)/2 -> 14.5 | Q6: =P6/$P$16*100 -> 4.0333797 | R6: =Q6 -> 4.0333797 | S6: =(S$18*R6)/100 -> 1.4116829 | T6: =(G6+M6+S6) -> 1.4116829 | U6: 0 | V6: 0 | W6: 0 | X6: 0
A7: 6.3 | D7: =(B7+C7)/2 -> 0 | E7: =D7/$D$16*100 -> 0 | F7: =F6+E7 -> 0 | G7: =(G$18*F7)/100 -> 0 | J7: =(H7+I7)/2 -> 0 | K7: =J7/$J$16*100 -> 0 | L7: =L6+K7 -> 0 | M7: =(M$18*L7)/100 -> 0 | N7: 30 | O7: 52 | P7: =(N7+O7)/2 -> 41 | Q7: =P7/$P$16*100 -> 11.404729 | R7: =R6+Q7 -> 15.438108 | S7: =(S$18*R7)/100 -> 5.403338 | T7: =(G7+M7+S7) -> 5.403338 | U7: 0 | V7: 0 | W7: 0 | X7: 7
A8: 4.8 | D8: =(B8+C8)/2 -> 0 | E8: =D8/$D$16*100 -> 0 | F8: =F7+E8 -> 0 | G8: =(G$18*F8)/100 -> 0 | H8: 6 | I8: 9 | J8: =(H8+I8)/2 -> 7.5 | K8: =J8/$J$16*100 -> 1.2931034 | L8: =L7+K8 -> 1.2931034 | M8: =(M$18*L8)/100 -> 0.51724138 | N8: 68 | O8: 75 | P8: =(N8+O8)/2 -> 71.5 | Q8: =P8/$P$16*100 -> 19.888734 | R8: =R7+Q8 -> 35.326843 | S8: =(S$18*R8)/100 -> 12.364395 | T8: =(G8+M8+S8) -> 12.881636 | U8: 0 | V8: 0 | W8: 5 | X8: 10
A9: 2.4 | D9: =(B9+C9)/2 -> 0 | E9: =D9/$D$16*100 -> 0 | F9: =F8+E9 -> 0 | G9: =(G$18*F9)/100 -> 0 | H9: 52 | I9: 54 | J9: =(H9+I9)/2 -> 53 | K9: =J9/$J$16*100 -> 9.137931 | L9: =L8+K9 -> 10.431034 | M9: =(M$18*L9)/100 -> 4.1724138 | N9: 105 | O9: 127 | P9: =(N9+O9)/2 -> 116 | Q9: =P9/$P$16*100 -> 32.267038 | R9: =R8+Q9 -> 67.59388 | S9: =(S$18*R9)/100 -> 23.657858 | T9: =(G9+M9+S9) -> 27.830272 | U9: 0 | V9: 10 | W9: 20 | X9: 25
A10: 1.2 | D10: =(B10+C10)/2 -> 0 | E10: =D10/$D$16*100 -> 0 | F10: =F9+E10 -> 0 | G10: =(G$18*F10)/100 -> 0 | H10: 98 | I10: 105 | J10: =(H10+I10)/2 -> 101.5 | K10: =J10/$J$16*100 -> 17.5 | L10: =L9+K10 -> 27.931034 | M10: =(M$18*L10)/100 -> 11.172414 | N10: 52 | O10: 77 | P10: =(N10+O10)/2 -> 64.5 | Q10: =P10/$P$16*100 -> 17.941586 | R10: =R9+Q10 -> 85.535466 | S10: =(S$18*R10)/100 -> 29.937413 | T10: =(G10+M10+S10) -> 41.109827 | U10: 5 | V10: 20 | W10: 30 | X10: 50
A11: 0.6 | D11: =(B11+C11)/2 -> 0 | E11: =D11/$D$16*100 -> 0 | F11: =F10+E11 -> 0 | G11: =(G$18*F11)/100 -> 0 | H11: 107 | I11: 99 | J11: =(H11+I11)/2 -> 103 | K11: =J11/$J$16*100 -> 17.758621 | L11: =L10+K11 -> 45.689655 | M11: =(M$18*L11)/100 -> 18.275862 | N11: 48 | O11: 56 | P11: =(N11+O11)/2 -> 52 | Q11: =P11/$P$16*100 -> 14.464534 | R11: =R10+Q11 -> 100 | S11: =(S$18*R11)/100 -> 35 | T11: =(G11+M11+S11) -> 53.275862 | U11: 15 | V11: 35 | W11: 55 | X11: 70
A12: 0.3 | B12: 15 | C12: 11 | D12: =(B12+C12)/2 -> 13 | E12: =D12/$D$16*100 -> 2.3111111 | F12: =F11+E12 -> 2.3111111 | G12: =(G$18*F12)/100 -> 0.57777778 | H12: 215 | I12: 203 | J12: =(H12+I12)/2 -> 209 | K12: =J12/$J$16*100 -> 36.034483 | L12: =L11+K12 -> 81.724138 | M12: =(M$18*L12)/100 -> 32.689655 | P12: =(N12+O12)/2 -> 0 | Q12: =P12/$P$16*100 -> 0 | R12: =R11+Q12 -> 100 | S12: =(S$18*R12)/100 -> 35 | T12: =(G12+M12+S12) -> 68.267433 | U12: 50 | V12: 65 | W12: 85 | X12: 95
A13: 0.15 | B13: 394 | C13: 422 | D13: =(B13+C13)/2 -> 408 | E13: =D13/$D$16*100 -> 72.533333 | F13: =F12+E13 -> 74.844444 | G13: =(G$18*F13)/100 -> 18.711111 | H13: 86 | I13: 103 | J13: =(H13+I13)/2 -> 94.5 | K13: =J13/$J$16*100 -> 16.293103 | L13: =L12+K13 -> 98.017241 | M13: =(M$18*L13)/100 -> 39.206897 | P13: =(N13+O13)/2 -> 0 | Q13: =P13/$P$16*100 -> 0 | R13: =R12+Q13 -> 100 | S13: =(S$18*R13)/100 -> 35 | T13: =(G13+M13+S13) -> 92.918008 | U13: 85 | V13: 90 | W13: 95 | X13: 100
A14: 0.075 | B14: 150 | C14: 131 | D14: =(B14+C14)/2 -> 140.5 | E14: =D14/$D$16*100 -> 24.977778 | F14: =F13+E14 -> 99.822222 | G14: =(G$18*F14)/100 -> 24.955556 | H14: 13 | I14: 6 | J14: =(H14+I14)/2 -> 9.5 | K14: =J14/$J$16*100 -> 1.637931 | L14: =L13+K14 -> 99.655172 | M14: =(M$18*L14)/100 -> 39.862069 | P14: =(N14+O14)/2 -> 0 | Q14: =P14/$P$16*100 -> 0 | R14: =R13+Q14 -> 100 | S14: =(S$18*R14)/100 -> 35 | T14: =(G14+M14+S14) -> 99.817625 | U14: 100 | V14: 100 | W14: 100 | X14: 100
A15: 0.0375 | B15: 1 | C15: 1 | D15: =(B15+C15)/2 -> 1 | E15: =D15/$D$16*100 -> 0.17777778 | F15: =F14+E15 -> 100 | G15: =(G$18*F15)/100 -> 25 | H15: 3 | I15: 1 | J15: =(H15+I15)/2 -> 2 | K15: =J15/$J$16*100 -> 0.34482759 | L15: =L14+K15 -> 100 | M15: =(M$18*L15)/100 -> 40 | P15: =(N15+O15)/2 -> 0 | Q15: =P15/$P$16*100 -> 0 | R15: =R14+Q15 -> 100 | S15: =(S$18*R15)/100 -> 35 | T15: =(G15+M15+S15) -> 100 | U15: 100 | V15: 100 | W15: 100 | X15: 100
A16: (%) | B16: =SUM(B6:B15) -> 560 | C16: =SUM(C6:C15) -> 565 | D16: =SUM(D6:D15) -> 562.5 | E16: =SUM(E6:E15) -> 100 | H16: =SUM(H6:H15) -> 580 | I16: =SUM(I6:I15) -> 580 | J16: =SUM(J6:J15) -> 580 | K16: =SUM(K6:K15) -> 100 | N16: =SUM(N6:N15) -> 315 | O16: =SUM(O6:O15) -> 404 | P16: =SUM(P6:P15) -> 359.5 | Q16: =SUM(Q6:Q15) -> 100 | T16: =(G18+M18+S18)/100 -> 1
A17: Mód Finura | B17: =(F6+F8+F9+F10+F11+F12+F13)/100 -> 0.77155556 | H17: =(L6+L8+L9+L10+L11+L12+L13)/100 -> 2.6508621 | N17: =(R6+R8+R9+R10+R11+R12+R13)/100 -> 4.9248957 | T17: =(T6+T8+T9+T10+T11+T12+T13)/100 -> 2.9769472 | U17: =(U6+U8+U9+U10+U11+U12+U13)/100 -> 1.55 | V17: =(V6+V8+V9+V10+V11+V12+V13)/100 -> 2.2 | W17: =(W6+W8+W9+W10+W11+W12+W13)/100 -> 2.9 | X17: =(X6+X8+X9+X10+X11+X12+X13)/100 -> 3.5
B18: Teor na mistura de areia fina | G18: 25 | H18: Teor na mistura de areia regular | M18: 40 | N18: Teor na mistura de areia grossa | S18: =100-G18-M18 -> 35
Z34: ⁭
AA43: ⁭

Sheet Granulometeria 1 Brita
A3: COMPOSIÇÃO GRANULOMÉTRICA DE UM AGREGADO GRAÚDO | L3: Data:
A4: Peneira com abertura de malha (ABNT NBR NM ISO 3310-1) | B4: Brita | G4: Percentagem, em massa, retida acumulada
G5: Zona Granulométrica (d/D)
B6: Ensaio 1 | C6: Ensaio 2 | D6: Média (g) | E6: Retido (%) | F6: Acum. (%) | G6: 4,75/12,5 | I6: 9,5/25 | K6: 19/31,5 | M6: 25/50 | O6: 37,5/75
G7: Lim Inf | H7: Lim Sup | I7: Lim Inf | J7: Lim Sup | K7: Lim Inf | L7: Lim Sup | M7: Lim Inf | N7: Lim Sup | O7: Lim Inf | P7: Lim Sup
A8: 75 | D8: =(B8+C8)/2 -> 0 | E8: =D8/$D$26*100 -> 0 | F8: =E8 -> 0 | G8: 0 | H8: 0 | I8: 0 | J8: 0 | K8: 0 | L8: 0 | M8: 0 | N8: 0 | O8: 0 | P8: 5
A9: 63 | D9: =(B9+C9)/2 -> 0 | E9: =D9/$D$26*100 -> 0 | F9: =F8+E9 -> 0 | G9: 0 | H9: 0 | I9: 0 | J9: 0 | K9: 0 | L9: 0 | M9: 0 | N9: 0 | O9: 5 | P9: 30
A10: 50 | D10: =(B10+C10)/2 -> 0 | E10: =D10/$D$26*100 -> 0 | F10: =F9+E10 -> 0 | G10: 0 | H10: 0 | I10: 0 | J10: 0 | K10: 0 | L10: 0 | M10: 0 | N10: 5 | O10: 75 | P10: 100
A11: 37.5 | D11: =(B11+C11)/2 -> 0 | E11: =D11/$D$26*100 -> 0 | F11: =F10+E11 -> 0 | G11: 0 | H11: 0 | I11: 0 | J11: 0 | K11: 0 | L11: 0 | M11: 5 | N11: 30 | O11: 90 | P11: 100
A12: 31.5 | D12: =(B12+C12)/2 -> 0 | E12: =D12/$D$26*100 -> 0 | F12: =F11+E12 -> 0 | G12: 0 | H12: 0 | I12: 0 | J12: 0 | K12: 0 | L12: 5 | M12: 75 | N12: 100 | O12: 95 | P12: 100
A13: 25 | D13: =(B13+C13)/2 -> 0 | E13: =D13/$D$26*100 -> 0 | F13: =F12+E13 -> 0 | G13: 0 | H13: 0 | I13: 0 | J13: 5 | K13: 5 | L13: 25 | M13: 87 | N13: 100 | O13: 100 | P13: 100
A14: 19 | B14: 98.7 | C14: 98.7 | D14: =(B14+C14)/2 -> 98.7 | E14: =D14/$D$26*100 -> 3.8739304 | F14: =F13+E14 -> 3.8739304 | G14: 0 | H14: 0 | I14: 2 | J14: 15 | K14: 65 | L14: 95 | M14: 95 | N14: 100 | O14: 100 | P14: 100
A15: 12.5 | B15: 124 | C15: 124 | D15: =(B15+C15)/2 -> 124 | E15: =D15/$D$26*100 -> 4.866944 | F15: =F14+E15 -> 8.7408745 | G15: 0 | H15: 5 | I15: 40 | J15: 65 | K15: 92 | L15: 100 | M15: 100 | N15: 100 | O15: 100 | P15: 100
A16: 9.5 | B16: 459.4 | C16: 459.4 | D16: =(B16+C16)/2 -> 459.4 | E16: =D16/$D$26*100 -> 18.031243 | F16: =F15+E16 -> 26.772117 | G16: 2 | H16: 15 | I16: 80 | J16: 100 | K16: 95 | L16: 100 | M16: 100 | N16: 100 | O16: 100 | P16: 100
A17: 6.3 | B17: 512 | C17: 512 | D17: =(B17+C17)/2 -> 512 | E17: =D17/$D$26*100 -> 20.095769 | F17: =F16+E17 -> 46.867886 | G17: 40 | H17: 65 | I17: 92 | J17: 100 | K17: 100 | L17: 100 | M17: 100 | N17: 100 | O17: 100 | P17: 100
A18: 4.8 | B18: 286.7 | C18: 286.7 | D18: =(B18+C18)/2 -> 286.7 | E18: =D18/$D$26*100 -> 11.252846 | F18: =F17+E18 -> 58.120732 | G18: 80 | H18: 100 | I18: 95 | J18: 100 | K18: 100 | L18: 100 | M18: 100 | N18: 100 | O18: 100 | P18: 100
A19: 2.4 | B19: 356 | C19: 356 | D19: =(B19+C19)/2 -> 356 | E19: =D19/$D$26*100 -> 13.972839 | F19: =F18+E19 -> 72.093571 | G19: 95 | H19: 100 | I19: 100 | J19: 100 | K19: 100 | L19: 100 | M19: 100 | N19: 100 | O19: 100 | P19: 100
A20: 1.2 | B20: 441 | C20: 441 | D20: =(B20+C20)/2 -> 441 | E20: =D20/$D$26*100 -> 17.309051 | F20: =F19+E20 -> 89.402622 | G20: 100 | H20: 100 | I20: 100 | J20: 100 | K20: 100 | L20: 100 | M20: 100 | N20: 100 | O20: 100 | P20: 100
A21: 0.6 | B21: 0 | C21: 0 | D21: =(B21+C21)/2 -> 0 | E21: =D21/$D$26*100 -> 0 | F21: =F20+E21 -> 89.402622 | G21: 100 | H21: 100 | I21: 100 | J21: 100 | K21: 100 | L21: 100 | M21: 100 | N21: 100 | O21: 100 | P21: 100
A22: 0.3 | B22: 270 | C22: 270 | D22: =(B22+C22)/2 -> 270 | E22: =D22/$D$26*100 -> 10.597378 | F22: =F21+E22 -> 100 | G22: 100 | H22: 100 | I22: 100 | J22: 100 | K22: 100 | L22: 100 | M22: 100 | N22: 100 | O22: 100 | P22: 100
A23: 0.15 | B23: 0 | C23: 0 | D23: =(B23+C23)/2 -> 0 | E23: =D23/$D$26*100 -> 0 | F23: =F22+E23 -> 100 | G23: 100 | H23: 100 | I23: 100 | J23: 100 | K23: 100 | L23: 100 | M23: 100 | N23: 100 | O23: 100 | P23: 100
A24: 0.075 | B24: 0 | C24: 0 | D24: =(B24+C24)/2 -> 0 | E24: =D24/$D$26*100 -> 0 | F24: =F23+E24 -> 100 | G24: 100 | H24: 100 | I24: 100 | J24: 100 | K24: 100 | L24: 100 | M24: 100 | N24: 100 | O24: 100 | P24: 100
A25: 0.0375 | B25: 0 | C25: 0 | D25: =(B25+C25)/2 -> 0 | E25: =D25/$D$26*100 -> 0 | F25: =F24+E25 -> 100 | G25: 100 | H25: 100 | I25: 100 | J25: 100 | K25: 100 | L25: 100 | M25: 100 | N25: 100 | O25: 100 | P25: 100
B26: =SUM(B8:B25) -> 2547.8 | C26: =SUM(C8:C25) -> 2547.8 | D26: =SUM(D13:D25) -> 2547.8 | E26: =SUM(E8:E25) -> 100 | G26: 100 | H26: 100 | I26: 100 | J26: 100 | K26: 100 | L26: 100 | M26: 100 | N26: 100 | O26: 100 | P26: 100
A27: Mód Finura | B27: =(F8+F11+F14+F16+F18+F19+F20+F21+F22+F23)/100 -> 5.3966559 | G27: =(G8+G11+G14+G16+G18+G19+G20+G21+G22+G23)/100 -> 5.77 | H27: =(H8+H11+H14+H16+H18+H19+H20+H21+H22+H23)/100 -> 6.15 | I27: =(I8+I11+I14+I16+I18+I19+I20+I21+I22+I23)/100 -> 6.77 | J27: =(J8+J11+J14+J16+J18+J19+J20+J21+J22+J23)/100 -> 7.15 | K27: =(K8+K11+K14+K16+K18+K19+K20+K21+K22+K23)/100 -> 7.6 | L27: =(L8+L11+L14+L16+L18+L19+L20+L21+L22+L23)/100 -> 7.95 | M27: =(M8+M11+M14+M16+M18+M19+M20+M21+M22+M23)/100 -> 8 | N27: =(N8+N11+N14+N16+N18+N19+N20+N21+N22+N23)/100 -> 8.3 | ... P27: =(P8+P11+P14+P16+P18+P19+P20+P21+P22+P23)/100 -> 9.05

Sheet Granulometria 2 Britas
A4: COMPOSIÇÃO GRANULOMÉTRICA DE UM AGREGADO GRAÚDO | T4: Data:
A5: Peneira com abertura de malha (ABNT NBR NM ISO 3310-1) | B5: Brita 1 | H5: Brita 2 | N5: Percentagem, em massa, retida acumulada
N6: Zona Granulométrica (d/D)
B7: Ensaio 1 | C7: Ensaio 2 | D7: Média (g) | E7: Retido (%) | F7: Acum. (%) | G7: Proporção (%) | H7: Ensaio 1 | I7: Ensaio 2 | J7: Média (g) | K7: Retido (%) | L7: Acum. (%) | M7: Proporção (%) | N7: Mescla das britas | O7: 4,75/12,5 | Q7: 9,5/25 | S7: 19/31,5 | U7: 25/50 | W7: 37,5/75
O8: Lim Inf | P8: Lim Sup | Q8: Lim Inf | R8: Lim Sup | S8: Lim Inf | T8: Lim Sup | U8: Lim Inf | V8: Lim Sup | W8: Lim Inf | X8: Lim Sup
A9: 75 | D9: =(B9+C9)/2 -> 0 | E9: =D9/$D$27*100 -> 0 | F9: =E9 -> 0 | G9: =$G$29*F9/100 -> 0 | J9: =(H9+I9)/2 -> 0 | K9: =J9/$D$27*100 -> 0 | L9: =K9 -> 0 | M9: =$M$29*L9/100 -> 0 | N9: =G9+M9 -> 0 | O9: 0 | P9: 0 | Q9: 0 | R9: 0 | S9: 0 | T9: 0 | U9: 0 | V9: 0 | W9: 0 | X9: 5
A10: 63 | D10: =(B10+C10)/2 -> 0 | E10: =D10/$D$27*100 -> 0 | F10: =F9+E10 -> 0 | G10: =$G$29*F10/100 -> 0 | J10: =(H10+I10)/2 -> 0 | K10: =J10/$D$27*100 -> 0 | L10: =L9+K10 -> 0 | M10: =$M$29*L10/100 -> 0 | N10: =G10+M10 -> 0 | O10: 0 | P10: 0 | Q10: 0 | R10: 0 | S10: 0 | T10: 0 | U10: 0 | V10: 0 | W10: 5 | X10: 30
A11: 50 | D11: =(B11+C11)/2 -> 0 | E11: =D11/$D$27*100 -> 0 | F11: =F10+E11 -> 0 | G11: =$G$29*F11/100 -> 0 | J11: =(H11+I11)/2 -> 0 | K11: =J11/$D$27*100 -> 0 | L11: =L10+K11 -> 0 | M11: =$M$29*L11/100 -> 0 | N11: =G11+M11 -> 0 | O11: 0 | P11: 0 | Q11: 0 | R11: 0 | S11: 0 | T11: 0 | U11: 0 | V11: 5 | W11: 75 | X11: 100
A12: 37.5 | D12: =(B12+C12)/2 -> 0 | E12: =D12/$D$27*100 -> 0 | F12: =F11+E12 -> 0 | G12: =$G$29*F12/100 -> 0 | J12: =(H12+I12)/2 -> 0 | K12: =J12/$D$27*100 -> 0 | L12: =L11+K12 -> 0 | M12: =$M$29*L12/100 -> 0 | N12: =G12+M12 -> 0 | O12: 0 | P12: 0 | Q12: 0 | R12: 0 | S12: 0 | T12: 0 | U12: 5 | V12: 30 | W12: 90 | X12: 100
A13: 31.5 | D13: =(B13+C13)/2 -> 0 | E13: =D13/$D$27*100 -> 0 | F13: =F12+E13 -> 0 | G13: =$G$29*F13/100 -> 0 | J13: =(H13+I13)/2 -> 0 | K13: =J13/$D$27*100 -> 0 | L13: =L12+K13 -> 0 | M13: =$M$29*L13/100 -> 0 | N13: =G13+M13 -> 0 | O13: 0 | P13: 0 | Q13: 0 | R13: 0 | S13: 0 | T13: 5 | U13: 75 | V13: 100 | W13: 95 | X13: 100
A14: 25 | D14: =(B14+C14)/2 -> 0 | E14: =D14/$D$27*100 -> 0 | F14: =F13+E14 -> 0 | G14: =$G$29*F14/100 -> 0 | J14: =(H14+I14)/2 -> 0 | K14: =J14/$D$27*100 -> 0 | L14: =L13+K14 -> 0 | M14: =$M$29*L14/100 -> 0 | N14: =G14+M14 -> 0 | O14: 0 | P14: 0 | Q14: 0 | R14: 5 | S14: 5 | T14: 25 | U14: 87 | V14: 100 | W14: 100 | X14: 100
A15: 19 | B15: 98.7 | C15: 98.7 | D15: =(B15+C15)/2 -> 98.7 | E15: =D15/$D$27*100 -> 3.8739304 | F15: =F14+E15 -> 3.8739304 | G15: =$G$29*F15/100 -> 0.96848261 | H15: 98.7 | I15: 98.7 | J15: =(H15+I15)/2 -> 98.7 | K15: =J15/$D$27*100 -> 3.8739304 | L15: =L14+K15 -> 3.8739304 | M15: =$M$29*L15/100 -> 2.9054478 | N15: =G15+M15 -> 3.8739304 | O15: 0 | P15: 0 | Q15: 2 | R15: 15 | S15: 65 | T15: 95 | U15: 95 | V15: 100 | W15: 100 | X15: 100
A16: 12.5 | B16: 124 | C16: 124 | D16: =(B16+C16)/2 -> 124 | E16: =D16/$D$27*100 -> 4.866944 | F16: =F15+E16 -> 8.7408745 | G16: =$G$29*F16/100 -> 2.1852186 | H16: 124 | I16: 124 | J16: =(H16+I16)/2 -> 124 | K16: =J16/$D$27*100 -> 4.866944 | L16: =L15+K16 -> 8.7408745 | M16: =$M$29*L16/100 -> 6.5556559 | N16: =G16+M16 -> 8.7408745 | O16: 0 | P16: 5 | Q16: 40 | R16: 65 | S16: 92 | T16: 100 | U16: 100 | V16: 100 | W16: 100 | X16: 100
A17: 9.5 | B17: 459.4 | C17: 459.4 | D17: =(B17+C17)/2 -> 459.4 | E17: =D17/$D$27*100 -> 18.031243 | F17: =F16+E17 -> 26.772117 | G17: =$G$29*F17/100 -> 6.6930293 | H17: 459.4 | I17: 459.4 | J17: =(H17+I17)/2 -> 459.4 | K17: =J17/$D$27*100 -> 18.031243 | L17: =L16+K17 -> 26.772117 | M17: =$M$29*L17/100 -> 20.079088 | N17: =G17+M17 -> 26.772117 | O17: 2 | P17: 15 | Q17: 80 | R17: 100 | S17: 95 | T17: 100 | U17: 100 | V17: 100 | W17: 100 | X17: 100
A18: 6.3 | B18: 512 | C18: 512 | D18: =(B18+C18)/2 -> 512 | E18: =D18/$D$27*100 -> 20.095769 | F18: =F17+E18 -> 46.867886 | G18: =$G$29*F18/100 -> 11.716972 | H18: 512 | I18: 512 | J18: =(H18+I18)/2 -> 512 | K18: =J18/$D$27*100 -> 20.095769 | L18: =L17+K18 -> 46.867886 | M18: =$M$29*L18/100 -> 35.150915 | N18: =G18+M18 -> 46.867886 | O18: 40 | P18: 65 | Q18: 92 | R18: 100 | S18: 100 | T18: 100 | U18: 100 | V18: 100 | W18: 100 | X18: 100
A19: 4.8 | B19: 286.7 | C19: 286.7 | D19: =(B19+C19)/2 -> 286.7 | E19: =D19/$D$27*100 -> 11.252846 | F19: =F18+E19 -> 58.120732 | G19: =$G$29*F19/100 -> 14.530183 | H19: 286.7 | I19: 286.7 | J19: =(H19+I19)/2 -> 286.7 | K19: =J19/$D$27*100 -> 11.252846 | L19: =L18+K19 -> 58.120732 | M19: =$M$29*L19/100 -> 43.590549 | N19: =G19+M19 -> 58.120732 | O19: 80 | P19: 100 | Q19: 95 | R19: 100 | S19: 100 | T19: 100 | U19: 100 | V19: 100 | W19: 100 | X19: 100
A20: 2.4 | B20: 356 | C20: 356 | D20: =(B20+C20)/2 -> 356 | E20: =D20/$D$27*100 -> 13.972839 | F20: =F19+E20 -> 72.093571 | G20: =$G$29*F20/100 -> 18.023393 | H20: 356 | I20: 356 | J20: =(H20+I20)/2 -> 356 | K20: =J20/$D$27*100 -> 13.972839 | L20: =L19+K20 -> 72.093571 | M20: =$M$29*L20/100 -> 54.070178 | N20: =G20+M20 -> 72.093571 | O20: 95 | P20: 100 | Q20: 100 | R20: 100 | S20: 100 | T20: 100 | U20: 100 | V20: 100 | W20: 100 | X20: 100
A21: 1.2 | B21: 441 | C21: 441 | D21: =(B21+C21)/2 -> 441 | E21: =D21/$D$27*100 -> 17.309051 | F21: =F20+E21 -> 89.402622 | G21: =$G$29*F21/100 -> 22.350655 | H21: 441 | I21: 441 | J21: =(H21+I21)/2 -> 441 | K21: =J21/$D$27*100 -> 17.309051 | L21: =L20+K21 -> 89.402622 | M21: =$M$29*L21/100 -> 67.051966 | N21: =G21+M21 -> 89.402622 | O21: 100 | P21: 100 | Q21: 100 | R21: 100 | S21: 100 | T21: 100 | U21: 100 | V21: 100 | W21: 100 | X21: 100
A22: 0.6 | B22: 0 | C22: 0 | D22: =(B22+C22)/2 -> 0 | E22: =D22/$D$27*100 -> 0 | F22: =F21+E22 -> 89.402622 | G22: =$G$29*F22/100 -> 22.350655 | H22: 0 | I22: 0 | J22: =(H22+I22)/2 -> 0 | K22: =J22/$D$27*100 -> 0 | L22: =L21+K22 -> 89.402622 | M22: =$M$29*L22/100 -> 67.051966 | N22: =G22+M22 -> 89.402622 | O22: 100 | P22: 100 | Q22: 100 | R22: 100 | S22: 100 | T22: 100 | U22: 100 | V22: 100 | W22: 100 | X22: 100
A23: 0.3 | B23: 270 | C23: 270 | D23: =(B23+C23)/2 -> 270 | E23: =D23/$D$27*100 -> 10.597378 | F23: =F22+E23 -> 100 | G23: =$G$29*F23/100 -> 25 | H23: 270 | I23: 270 | J23: =(H23+I23)/2 -> 270 | K23: =J23/$D$27*100 -> 10.597378 | L23: =L22+K23 -> 100 | M23: =$M$29*L23/100 -> 75 | N23: =G23+M23 -> 100 | O23: 100 | P23: 100 | Q23: 100 | R23: 100 | S23: 100 | T23: 100 | U23: 100 | V23: 100 | W23: 100 | X23: 100
A24: 0.15 | B24: 0 | C24: 0 | D24: =(B24+C24)/2 -> 0 | E24: =D24/$D$27*100 -> 0 | F24: =F23+E24 -> 100 | G24: =$G$29*F24/100 -> 25 | H24: 0 | I24: 0 | J24: =(H24+I24)/2 -> 0 | K24: =J24/$D$27*100 -> 0 | L24: =L23+K24 -> 100 | M24: =$M$29*L24/100 -> 75 | N24: =G24+M24 -> 100 | O24: 100 | P24: 100 | Q24: 100 | R24: 100 | S24: 100 | T24: 100 | U24: 100 | V24: 100 | W24: 100 | X24: 100
A25: 0.075 | B25: 0 | C25: 0 | D25: =(B25+C25)/2 -> 0 | E25: =D25/$D$27*100 -> 0 | F25: =F24+E25 -> 100 | G25: =$G$29*F25/100 -> 25 | H25: 0 | I25: 0 | J25: =(H25+I25)/2 -> 0 | K25: =J25/$D$27*100 -> 0 | L25: =L24+K25 -> 100 | M25: =$M$29*L25/100 -> 75 | N25: =G25+M25 -> 100 | O25: 100 | P25: 100 | Q25: 100 | R25: 100 | S25: 100 | T25: 100 | U25: 100 | V25: 100 | W25: 100 | X25: 100
A26: 0.0375 | B26: 0 | C26: 0 | D26: =(B26+C26)/2 -> 0 | E26: =D26/$D$27*100 -> 0 | F26: =F25+E26 -> 100 | G26: =$G$29*F26/100 -> 25 | H26: 0 | I26: 0 | J26: =(H26+I26)/2 -> 0 | K26: =J26/$D$27*100 -> 0 | L26: =L25+K26 -> 100 | M26: =$M$29*L26/100 -> 75 | N26: =G26+M26 -> 100 | O26: 100 | P26: 100 | Q26: 100 | R26: 100 | S26: 100 | T26: 100 | U26: 100 | V26: 100 | W26: 100 | X26: 100
B27: =SUM(B9:B26) -> 2547.8 | C27: =SUM(C9:C26) -> 2547.8 | D27: =SUM(D14:D26) -> 2547.8 | E27: =SUM(E9:E26) -> 100 | H27: =SUM(H9:H26) -> 2547.8 | I27: =SUM(I9:I26) -> 2547.8 | J27: =SUM(J14:J26) -> 2547.8 | K27: =SUM(K9:K26) -> 100 | O27: 100 | P27: 100 | Q27: 100 | R27: 100 | S27: 100 | T27: 100 | U27: 100 | V27: 100 | W27: 100 | X27: 100
A28: Mód Finura | B28: =(F9+F12+F15+F17+F19+F20+F21+F22+F23+F24)/100 -> 5.3966559 | H28: =(L9+L12+L15+L17+L19+L20+L21+L22+L23+L24)/100 -> 5.3966559 | N28: =(N9+N12+N15+N17+N19+N20+N21+N22+N23+N24)/100 -> 5.3966559 | O28: =(O9+O12+O15+O17+O19+O20+O21+O22+O23+O24)/100 -> 5.77 | P28: =(P9+P12+P15+P17+P19+P20+P21+P22+P23+P24)/100 -> 6.15 | Q28: =(Q9+Q12+Q15+Q17+Q19+Q20+Q21+Q22+Q23+Q24)/100 -> 6.77 | R28: =(R9+R12+R15+R17+R19+R20+R21+R22+R23+R24)/100 -> 7.15 | S28: =(S9+S12+S15+S17+S19+S20+S21+S22+S23+S24)/100 -> 7.6 | T28: =(T9+T12+T15+T17+T19+T20+T21+T22+T23+T24)/100 -> 7.95 | U28: =(U9+U12+U15+U17+U19+U20+U21+U22+U23+U24)/100 -> 8 | ... X28: =(X9+X12+X15+X17+X19+X20+X21+X22+X23+X24)/100 -> 9.05
B29: Teor na mistura da brita 1 | G29: 25 | H29: Teor na mistura da brita 2 | M29: =100-G29 -> 75

Sheet Empacotamento
A2: Determinação da massa unitária compactada de misturas e índice de volume de vazios ABNT NBR NM 45 | I2: Mínimos de vazios das misturas | R2: m | S2: Traço | T2: Cimento | U2: =CONCATENATE($D$4) -> Brita 2 | V2: =CONCATENATE($D$5) -> Brita 1 | W2: =CONCATENATE($D$6) -> Brita 0 | X2: =CONCATENATE($D$7) -> Areia Grossa | Y2: =CONCATENATE($D$8) -> Areia Média | Z2: =CONCATENATE($D$9) -> Areia Fina
D3: Massa Específica (kg/m3) | U3: =IF(U$2="","",IF(U$2="Brita 2","B",IF(U$2="Brita 1","B",IF(U$2="Brita 0","B",IF(U$2="Areia Grossa","A",IF(U$2="Areia Média","A",IF(U$2="Areia Fina","A","X"))))))) -> B | V3: =IF(V$2="","",IF(V$2="Brita 2","B",IF(V$2="Brita 1","B",IF(V$2="Brita 0","B",IF(V$2="Areia Grossa","A",IF(V$2="Areia Média","A",IF(V$2="Areia Fina","A","X"))))))) -> B | W3: =IF(W$2="","",IF(W$2="Brita 2","B",IF(W$2="Brita 1","B",IF(W$2="Brita 0","B",IF(W$2="Areia Grossa","A",IF(W$2="Areia Média","A",IF(W$2="Areia Fina","A","X"))))))) -> B | X3: =IF(X$2="","",IF(X$2="Brita 2","B",IF(X$2="Brita 1","B",IF(X$2="Brita 0","B",IF(X$2="Areia Grossa","A",IF(X$2="Areia Média","A",IF(X$2="Areia Fina","A","X"))))))) -> A | Y3: =IF(Y$2="","",IF(Y$2="Brita 2","B",IF(Y$2="Brita 1","B",IF(Y$2="Brita 0","B",IF(Y$2="Areia Grossa","A",IF(Y$2="Areia Média","A",IF(Y$2="Areia Fina","A","X"))))))) -> A | Z3: =IF(Z$2="","",IF(Z$2="Brita 2","B",IF(Z$2="Brita 1","B",IF(Z$2="Brita 0","B",IF(Z$2="Areia Grossa","A",IF(Z$2="Areia Média","A",IF(Z$2="Areia Fina","A","X"))))))) -> A
A4: Peso Recipiente (kg) | C4: 3.915 | D4: Brita 2 | E4: 3000 | F4: =CONCATENATE("Melhor ",INDEX($AC$13:$AD$19,MATCH($D$4,$AC$13:$AC$19,0),2),"/",INDEX($AC$13:$AD$19,MATCH($D$5,$AC$13:$AC$19,0),2)) -> Melhor B2/B1 | G4: =INDEX(F12:F23,MATCH(O4,G12:G23,0)) -> 2949 | I4: =CONCATENATE(INDEX($AC$13:$AD$19,MATCH($D$4,AC13:AC19,0),2)," + ",INDEX($AC$13:$AD$19,MATCH($D$5,AC13:AC19,0),2)) -> B2 + B1 | O4: =MIN(G12:G23) -> 44.290268 | R4: 5 | S4: =CONCATENATE("1:",$R$4,) -> 1:5 | T4: 1 | U4: =$R$4-$V$4-$W$4-$X$4-$Y$4-$Z$4 -> 0.225225 | V4: =INDEX($B$12:$B$23,MATCH($O$4,$G$12:$G$23,0))/100*($R$4-W$4-X$4-Y$4-Z$4) -> 0.096525 | W4: =IF(W2="",0,INDEX($B$27:$B$38,MATCH($O$5,$G$27:$G$38,0))/100*($R$4-X$4-Y$4-Z$4)) -> 1.287 | X4: =IF(X2="",0,INDEX($B$42:$B$53,MATCH($O$6,$G$42:$G$53,0))/100*($R$4-Y$4-Z$4)) -> 1.31625 | Y4: =IF(Y2="",0,INDEX($B$57:$B$68,MATCH($O$7,$G$57:$G$68,0))/100*($R$4-Z$4)) -> 1.575 | Z4: =IF(Z2="",0,$R$4*INDEX($B$72:$B$83,MATCH($O$8,$G$72:$G$83,0))/100) -> 0.5
A5: Dimensões do Recipiente (cm) | C5: 25 | D5: Brita 1 | E5: 2830 | F5: =IF(D6="","",CONCATENATE("Melhor ",INDEX($AC$13:$AD$19,MATCH($D$4,$AC$13:$AC$19,0),2),"/",INDEX($AC$13:$AD$19,MATCH($D$5,$AC$13:$AC$19,0),2),"/",INDEX($AC$13:$AD$19,MATCH($D$6,$AC$13:$AC$19,0),2))) -> Melhor B2/B1/B0 | G5: =INDEX(F27:F38,MATCH(O5,G27:G38,0)) -> 2669.8 | I5: =IF(D6="","",CONCATENATE(INDEX($AC$13:$AD$19,MATCH($D$4,AC13:AC19,0),2)," + ",INDEX($AC$13:$AD$19,MATCH($D$5,AC13:AC19,0),2)," + ",INDEX($AC$13:$AD$19,MATCH($D$6,$AC$13:$AC$19,0),2))) -> B2 + B1 + B0 | O5: =IF(I5="","",MIN(G27:G38)) -> 31.581991 | R5: Conferência dos % | U5: =1-V5 -> 0.7 | V5: =INDEX($B$12:$B$23,MATCH($O$4,$G$12:$G$23,0))/100 -> 0.3 | W5: =IF(W2="","",INDEX($B$27:$B$38,MATCH($O$5,$G$27:$G$38,0))/100) -> 0.8 | X5: =IF(X2="","",INDEX($B$42:$B$53,MATCH($O$6,$G$42:$G$53,0))/100) -> 0.45 | Y5: =IF(Y2="","",INDEX($B$57:$B$68,MATCH($O$7,$G$57:$G$68,0))/100) -> 0.35 | Z5: =IF(Z2="","",INDEX($B$72:$B$83,MATCH($O$8,$G$72:$G$83,0))/100) -> 0.1
C6: 25 | D6: Brita 0 | E6: 2600 | F6: =IF(D7="","",CONCATENATE("Melhor ",INDEX($AC$13:$AD$19,MATCH($D$4,$AC$13:$AC$19,0),2),"/",INDEX($AC$13:$AD$19,MATCH($D$5,$AC$13:$AC$19,0),2),"/",INDEX($AC$13:$AD$19,MATCH($D$6,$AC$13:$AC$19,0),2),"/",INDEX($AC$13:$AD$19,MATCH($D$7,$AC$13:$AC$19,0),2))) -> Melhor B2/B1/B0/AG | G6: =INDEX(F42:F53,MATCH(O6,G42:G53,0)) -> 2651.89 | I6: =IF(D7="","",CONCATENATE(INDEX($AC$13:$AD$19,MATCH($D$4,AC13:AC19,0),2)," + ",INDEX($AC$13:$AD$19,MATCH($D$5,AC13:AC19,0),2)," + ",INDEX($AC$13:$AD$19,MATCH($D$6,$AC$13:$AC$19,0),2)," + ",INDEX($AC$13:$AD$19,MATCH($D$7,$AC$13:$AC$19,0),2))) -> B2 + B1 + B0 + AG | O6: =IF(I6="","",MIN(G42:G53)) -> 23.170267
C7: 25 | D7: Areia Grossa | E7: 2630 | F7: =IF(D8="","",CONCATENATE("Melhor ",INDEX($AC$13:$AD$19,MATCH($D$4,$AC$13:$AC$19,0),2),"/",INDEX($AC$13:$AD$19,MATCH($D$5,$AC$13:$AC$19,0),2),"/",INDEX($AC$13:$AD$19,MATCH($D$6,$AC$13:$AC$19,0),2),"/",INDEX($AC$13:$AD$19,MATCH($D$7,$AC$13:$AC$19,0),2),"/",INDEX($AC$13:$AD$19,MATCH($D$8,$AC$13:$AC$19,0),2))) -> Melhor B2/B1/B0/AG/AM | G7: =INDEX(F57:F68,MATCH(O7,G57:G68,0)) -> 2644.2285 | I7: =IF(D8="","",CONCATENATE(INDEX($AC$13:$AD$19,MATCH($D$4,AC13:AC19,0),2)," + ",INDEX($AC$13:$AD$19,MATCH($D$5,AC13:AC19,0),2)," + ",INDEX($AC$13:$AD$19,MATCH($D$6,$AC$13:$AC$19,0),2)," + ",INDEX($AC$13:$AD$19,MATCH($D$7,$AC$13:$AC$19,0),2)," + ",INDEX($AC$13:$AD$19,MATCH($D$8,$AC$13:$AC$19,0),2))) -> B2 + B1 + B0 + AG + AM | O7: =IF(I7="","",MIN(G57:G68)) -> 22.052122 | R7: Proporção | U7: =IF(U$2="","",IF(U$3="B",U$4/$U$8,IF(U$3="A",U$4/$W$8,"X"))) -> 0.14 | V7: =IF(V$2="","",IF(V$3="B",V$4/$U$8,IF(V$3="A",V$4/$W$8,"X"))) -> 0.06 | W7: =IF(W$2="","",IF(W$3="B",W$4/$U$8,IF(W$3="A",W$4/$W$8,"X"))) -> 0.8 | X7: =IF(X$2="","",IF(X$3="B",X$4/$U$8,IF(X$3="A",X$4/$W$8,"X"))) -> 0.38813122 | Y7: =IF(Y$2="","",IF(Y$3="B",Y$4/$U$8,IF(Y$3="A",Y$4/$W$8,"X"))) -> 0.46443052 | Z7: =IF(Z$2="","",IF(Z$3="B",Z$4/$U$8,IF(Z$3="A",Z$4/$W$8,"X"))) -> 0.14743826
A8: Volume (l) (mínimo 10 l) | C8: =IF(C5*C6*C7/1000<10,"Aumentar Vol",C5*C6*C7/1000) -> 15.625 | D8: Areia Média | E8: 2630 | F8: =IF(D9="","",CONCATENATE("Melhor ",INDEX($AC$13:$AD$19,MATCH($D$4,$AC$13:$AC$19,0),2),"/",INDEX($AC$13:$AD$19,MATCH($D$5,$AC$13:$AC$19,0),2),"/",INDEX($AC$13:$AD$19,MATCH($D$6,$AC$13:$AC$19,0),2),"/",INDEX($AC$13:$AD$19,MATCH($D$7,$AC$13:$AC$19,0),2),"/",INDEX($AC$13:$AD$19,MATCH($D$8,$AC$13:$AC$19,0),2),"/",INDEX($AC$13:$AD$19,MATCH($D$9,$AC$13:$AC$19,0),2))) -> Melhor B2/B1/B0/AG/AM/AF | G8: =INDEX(F72:F83,MATCH(O8,G72:G83,0)) -> 2642.8056 | I8: =IF(D9="","",CONCATENATE(INDEX($AC$13:$AD$19,MATCH($D$4,AC13:AC19,0),2)," + ",INDEX($AC$13:$AD$19,MATCH($D$5,AC13:AC19,0),2)," + ",INDEX($AC$13:$AD$19,MATCH($D$6,$AC$13:$AC$19,0),2)," + ",INDEX($AC$13:$AD$19,MATCH($D$7,$AC$13:$AC$19,0),2)," + ",INDEX($AC$13:$AD$19,MATCH($D$8,$AC$13:$AC$19,0),2)," + ",INDEX($AC$13:$AD$19,MATCH($D$9,$AC$13:$AC$19,0),2))) -> B2 + B1 + B0 + AG + AM + AF | O8: =IF(I8="","",MIN(G72:G83)) -> 19.581222 | R8: Total | T8: B | U8: =SUMIF($U$3:$Z$3,"=B",$U$4:$Z$4) -> 1.60875 | V8: A | W8: =SUMIF($U$3:$Z$3,"=A",$U$4:$Z$4) -> 3.39125
D9: Areia Fina | E9: 2630
A10: =CONCATENATE("Determinação da massa unitária compactada da ",$D$4," e ",D5) -> Determinação da massa unitária compactada da Brita 2 e Brita 1
A11: =CONCATENATE(INDEX($AC$13:$AD$19,MATCH($D$4,$AC$13:$AC$19,0),2)," (%)") -> B2 (%) | B11: =CONCATENATE(INDEX($AC$13:$AD$19,MATCH($D$5,$AC$13:$AC$19,0),2)," (%)") -> B1 (%) | C11: Massa compactada da mistura (kg) | D11: Massa compactada da mistura sem o recepciente (kg) | E11: Massa Unitária Compactada Final (kg/m3) | F11: Massa Específica da Mistura (kg/m3) | G11: Índice de Volume de Vazios (%)
A12: 100 | B12: =IF(C12="","",100-A12) -> 0 | C12: 28.52 | D12: =IF(C12="","",C12-$C$4) -> 24.605 | E12: =IF(C12="","",(D12/$C$8)*1000) -> 1574.72 | F12: =IF(C12="","",(($E$4*A12)+($E$5*B12))/100) -> 3000 | G12: =IF(C12="","",((F12-E12)/F12)*100) -> 47.509333 | AC12: Materiais
A13: 90 | B13: =IF(C13="","",100-A13) -> 10 | C13: 28.635 | D13: =IF(C13="","",C13-$C$4) -> 24.72 | E13: =IF(C13="","",(D13/$C$8)*1000) -> 1582.08 | F13: =IF(C13="","",(($E$4*A13)+($E$5*B13))/100) -> 2983 | G13: =IF(C13="","",((F13-E13)/F13)*100) -> 46.96346
A14: 80 | B14: =IF(C14="","",100-A14) -> 20 | C14: 29.14 | D14: =IF(C14="","",C14-$C$4) -> 25.225 | E14: =IF(C14="","",(D14/$C$8)*1000) -> 1614.4 | F14: =IF(C14="","",(($E$4*A14)+($E$5*B14))/100) -> 2966 | G14: =IF(C14="","",((F14-E14)/F14)*100) -> 45.569791 | AC14: Brita 2 | AD14: B2
A15: 70 | B15: =IF(C15="","",100-A15) -> 30 | C15: 29.585 | D15: =IF(C15="","",C15-$C$4) -> 25.67 | E15: =IF(C15="","",(D15/$C$8)*1000) -> 1642.88 | F15: =IF(C15="","",(($E$4*A15)+($E$5*B15))/100) -> 2949 | G15: =IF(C15="","",((F15-E15)/F15)*100) -> 44.290268 | AC15: Brita 1 | AD15: B1
A16: 65 | B16: =IF(C16="","",100-A16) -> 35 | C16: 28.6 | D16: =IF(C16="","",C16-$C$4) -> 24.685 | E16: =IF(C16="","",(D16/$C$8)*1000) -> 1579.84 | F16: =IF(C16="","",(($E$4*A16)+($E$5*B16))/100) -> 2940.5 | G16: =IF(C16="","",((F16-E16)/F16)*100) -> 46.273083 | AC16: Brita 0 | AD16: B0
A17: 60 | B17: =IF(C17="","",100-A17) -> 40 | C17: 29.3 | D17: =IF(C17="","",C17-$C$4) -> 25.385 | E17: =IF(C17="","",(D17/$C$8)*1000) -> 1624.64 | F17: =IF(C17="","",(($E$4*A17)+($E$5*B17))/100) -> 2932 | G17: =IF(C17="","",((F17-E17)/F17)*100) -> 44.589359 | AC17: Areia Grossa | AD17: AG
A18: 50 | B18: =IF(C18="","",100-A18) -> 50 | C18: 29.024 | D18: =IF(C18="","",C18-$C$4) -> 25.109 | E18: =IF(C18="","",(D18/$C$8)*1000) -> 1606.976 | F18: =IF(C18="","",(($E$4*A18)+($E$5*B18))/100) -> 2915 | G18: =IF(C18="","",((F18-E18)/F18)*100) -> 44.872178 | AC18: Areia Média | AD18: AM
A19: 40 | B19: =IF(C19="","",100-A19) -> 60 | C19: 28.635 | D19: =IF(C19="","",C19-$C$4) -> 24.72 | E19: =IF(C19="","",(D19/$C$8)*1000) -> 1582.08 | F19: =IF(C19="","",(($E$4*A19)+($E$5*B19))/100) -> 2898 | G19: =IF(C19="","",((F19-E19)/F19)*100) -> 45.407867 | AC19: Areia Fina | AD19: AF
B20: =IF(C20="","",100-A20) | D20: =IF(C20="","",C20-$C$4) | E20: =IF(C20="","",(D20/$C$8)*1000) | F20: =IF(C20="","",(($E$4*A20)+($E$5*B20))/100) | G20: =IF(C20="","",((F20-E20)/F20)*100)
B21: =IF(C21="","",100-A21) | D21: =IF(C21="","",C21-$C$4) | E21: =IF(C21="","",(D21/$C$8)*1000) | F21: =IF(C21="","",(($E$4*A21)+($E$5*B21))/100) | G21: =IF(C21="","",((F21-E21)/F21)*100)
B22: =IF(C22="","",100-A22) | D22: =IF(C22="","",C22-$C$4) | E22: =IF(C22="","",(D22/$C$8)*1000) | F22: =IF(C22="","",(($E$4*A22)+($E$5*B22))/100) | G22: =IF(C22="","",((F22-E22)/F22)*100)
B23: =IF(C23="","",100-A23) | D23: =IF(C23="","",C23-$C$4) | E23: =IF(C23="","",(D23/$C$8)*1000) | F23: =IF(C23="","",(($E$4*A23)+($E$5*B23))/100) | G23: =IF(C23="","",((F23-E23)/F23)*100)
A25: =CONCATENATE("Determinação da massa unitária compactada da ",$D$4,"/",$D$5," e ",$D$6) -> Determinação da massa unitária compactada da Brita 2/Brita 1 e Brita 0
A26: =CONCATENATE(INDEX($AC$13:$AD$19,MATCH($D$4,$AC$13:$AC$19,0),2),"/",INDEX($AC$13:$AD$19,MATCH($D$5,$AC$13:$AC$19,0),2)," (%)") -> B2/B1 (%) | B26: =CONCATENATE(INDEX($AC$13:$AD$19,MATCH($D$6,$AC$13:$AC$19,0),2)," (%)") -> B0 (%) | C26: Massa compactada da mistura (kg) | D26: Massa compactada da mistura sem o recepciente (kg) | E26: Massa Unitária Compactada Final (kg/m3) | F26: Massa Específica da Mistura (kg/m3) | G26: Índice de Volume de Vazios (%)
A27: 100 | B27: =IF(C27="","",100-A27) -> 0 | C27: 29.545 | D27: =IF(C27="","",C27-$C$4) -> 25.63 | E27: =IF(C27="","",(D27/$C$8)*1000) -> 1640.32 | F27: =IF(C27="","",(($G$4*A27)+($E$6*B27))/100) -> 2949 | G27: =IF(C27="","",((F27-E27)/F27)*100) -> 44.377077
A28: 90 | B28: =IF(C28="","",100-A28) -> 10 | C28: 31.23 | D28: =IF(C28="","",C28-$C$4) -> 27.315 | E28: =IF(C28="","",(D28/$C$8)*1000) -> 1748.16 | F28: =IF(C28="","",(($G$4*A28)+($E$6*B28))/100) -> 2914.1 | G28: =IF(C28="","",((F28-E28)/F28)*100) -> 40.010295
A29: 80 | B29: =IF(C29="","",100-A29) -> 20 | C29: 32.356 | D29: =IF(C29="","",C29-$C$4) -> 28.441 | E29: =IF(C29="","",(D29/$C$8)*1000) -> 1820.224 | F29: =IF(C29="","",(($G$4*A29)+($E$6*B29))/100) -> 2879.2 | G29: =IF(C29="","",((F29-E29)/F29)*100) -> 36.780217
A30: 70 | B30: =IF(C30="","",100-A30) -> 30 | C30: 32.998 | D30: =IF(C30="","",C30-$C$4) -> 29.083 | E30: =IF(C30="","",(D30/$C$8)*1000) -> 1861.312 | F30: =IF(C30="","",(($G$4*A30)+($E$6*B30))/100) -> 2844.3 | G30: =IF(C30="","",((F30-E30)/F30)*100) -> 34.559927
A31: 65 | B31: =IF(C31="","",100-A31) -> 35 | C31: 33.455 | D31: =IF(C31="","",C31-$C$4) -> 29.54 | E31: =IF(C31="","",(D31/$C$8)*1000) -> 1890.56 | F31: =IF(C31="","",(($G$4*A31)+($E$6*B31))/100) -> 2826.85 | G31: =IF(C31="","",((F31-E31)/F31)*100) -> 33.121319
A32: 60 | B32: =IF(C32="","",100-A32) -> 40 | C32: 31.556 | D32: =IF(C32="","",C32-$C$4) -> 27.641 | E32: =IF(C32="","",(D32/$C$8)*1000) -> 1769.024 | F32: =IF(C32="","",(($G$4*A32)+($E$6*B32))/100) -> 2809.4 | G32: =IF(C32="","",((F32-E32)/F32)*100) -> 37.031964
A33: 55 | B33: =IF(C33="","",100-A33) -> 45 | C33: 33.2 | D33: =IF(C33="","",C33-$C$4) -> 29.285 | E33: =IF(C33="","",(D33/$C$8)*1000) -> 1874.24 | F33: =IF(C33="","",(($G$4*A33)+($E$6*B33))/100) -> 2791.95 | G33: =IF(C33="","",((F33-E33)/F33)*100) -> 32.869858
A34: 50 | B34: =IF(C34="","",100-A34) -> 50 | C34: 32.5 | D34: =IF(C34="","",C34-$C$4) -> 28.585 | E34: =IF(C34="","",(D34/$C$8)*1000) -> 1829.44 | F34: =IF(C34="","",(($G$4*A34)+($E$6*B34))/100) -> 2774.5 | G34: =IF(C34="","",((F34-E34)/F34)*100) -> 34.062354
A35: 40 | B35: =IF(C35="","",100-A35) -> 60 | C35: 31.3 | D35: =IF(C35="","",C35-$C$4) -> 27.385 | E35: =IF(C35="","",(D35/$C$8)*1000) -> 1752.64 | F35: =IF(C35="","",(($G$4*A35)+($E$6*B35))/100) -> 2739.6 | G35: =IF(C35="","",((F35-E35)/F35)*100) -> 36.025697
A36: 30 | B36: =IF(C36="","",100-A36) -> 70 | C36: 32.567 | D36: =IF(C36="","",C36-$C$4) -> 28.652 | E36: =IF(C36="","",(D36/$C$8)*1000) -> 1833.728 | F36: =IF(C36="","",(($G$4*A36)+($E$6*B36))/100) -> 2704.7 | G36: =IF(C36="","",((F36-E36)/F36)*100) -> 32.202167
A37: 20 | B37: =IF(C37="","",100-A37) -> 80 | C37: 32.456 | D37: =IF(C37="","",C37-$C$4) -> 28.541 | E37: =IF(C37="","",(D37/$C$8)*1000) -> 1826.624 | F37: =IF(C37="","",(($G$4*A37)+($E$6*B37))/100) -> 2669.8 | G37: =IF(C37="","",((F37-E37)/F37)*100) -> 31.581991
B38: =IF(C38="","",100-A38) | D38: =IF(C38="","",C38-$C$4) | E38: =IF(C38="","",(D38/$C$8)*1000) | F38: =IF(C38="","",(($G$4*A38)+($E$6*B38))/100) | G38: =IF(C38="","",((F38-E38)/F38)*100)
A40: =CONCATENATE("Determinação da massa unitária compactada da ",$D$4,"/",$D$5,"/",$D$6," e ",$D$7) -> Determinação da massa unitária compactada da Brita 2/Brita 1/Brita 0 e Areia Grossa
A41: =CONCATENATE(INDEX($AC$13:$AD$19,MATCH($D$4,$AC$13:$AC$19,0),2),"/",INDEX($AC$13:$AD$19,MATCH($D$5,$AC$13:$AC$19,0),2),"/",INDEX($AC$13:$AD$19,MATCH($D$6,$AC$13:$AC$19,0),2)," (%)") -> B2/B1/B0 (%) | B41: =CONCATENATE(INDEX($AC$13:$AD$19,MATCH($D$7,$AC$13:$AC$19,0),2)," (%)") -> AG (%) | C41: Massa compactada da mistura (kg) | D41: Massa compactada da mistura sem o recepciente (kg) | E41: Massa Unitária Compactada Final (kg/m3) | F41: Massa Específica da Mistura (kg/m3) | G41: Índice de Volume de Vazios (%)
A42: 100 | B42: =IF(C42="","",100-A42) -> 0 | C42: 29.545 | D42: =IF(C42="","",C42-$C$4) -> 25.63 | E42: =IF(C42="","",(D42/$C$8)*1000) -> 1640.32 | F42: =IF(C42="","",(($G$5*A42)+($E$7*B42))/100) -> 2669.8 | G42: =IF(C42="","",((F42-E42)/F42)*100) -> 38.560192
A43: 90 | B43: =IF(C43="","",100-A43) -> 10 | C43: 31.23 | D43: =IF(C43="","",C43-$C$4) -> 27.315 | E43: =IF(C43="","",(D43/$C$8)*1000) -> 1748.16 | F43: =IF(C43="","",(($G$5*A43)+($E$7*B43))/100) -> 2665.82 | G43: =IF(C43="","",((F43-E43)/F43)*100) -> 34.423179
...

Sheet Traços
M1: SOMENTE SE FOR TRABALHAR COM 4 TRAÇOS
A2: INTERMEDIÁRIO | E2: Traço (m) | G2: RICO | K2: Traço (m) | M2: INTERMEDIÁRIO 2 | Q2: Traço (m) | S2: POBRE | W2: Traço (m)
A3: =CONCATENATE("Traço unitário (1:",E$3,")") -> Traço unitário (1:5) | E3: 5 | G3: =CONCATENATE("Traço unitário (1:",K$3,")") -> Traço unitário (1:3) | K3: 3 | M3: =CONCATENATE("Traço unitário (1:",Q$3,")") -> Traço unitário (1:6) | Q3: 6 | S3: =CONCATENATE("Traço unitário (1:",W$3,")") -> Traço unitário (1:7) | W3: 7
A4: % argam | B4: Cim | C4: Areia | D4: Brita | G4: % argam | H4: Cim | I4: Areia | J4: Brita | M4: % argam | N4: Cim | O4: Areia | P4: Brita | S4: % argam | T4: Cim | U4: Areia | V4: Brita
A5: 50 | B5: 1 | C5: =(($E$3+1)*(A5/100))-1 -> 2 | D5: =($E$3-C5) -> 3 | G5: 50 | H5: 1 | I5: =(($K$3+1)*(G5/100))-1 -> 1 | J5: =($K$3-I5) -> 2 | M5: 50 | N5: 1 | O5: =(($Q$3+1)*(M5/100))-1 -> 2.5 | P5: =($Q$3-O5) -> 3.5 | S5: 50 | T5: 1 | U5: =(($W$3+1)*(S5/100))-1 -> 3 | V5: =($W$3-U5) -> 4
A6: 52 | B6: 1 | C6: =(($E$3+1)*(A6/100))-1 -> 2.12 | D6: =($E$3-C6) -> 2.88 | G6: 52 | H6: 1 | I6: =(($K$3+1)*(G6/100))-1 -> 1.08 | J6: =($K$3-I6) -> 1.92 | M6: 52 | N6: 1 | O6: =(($Q$3+1)*(M6/100))-1 -> 2.64 | P6: =($Q$3-O6) -> 3.36 | S6: 52 | T6: 1 | U6: =(($W$3+1)*(S6/100))-1 -> 3.16 | V6: =($W$3-U6) -> 3.84
A7: 54 | B7: 1 | C7: =(($E$3+1)*(A7/100))-1 -> 2.24 | D7: =($E$3-C7) -> 2.76 | G7: 54 | H7: 1 | I7: =(($K$3+1)*(G7/100))-1 -> 1.16 | J7: =($K$3-I7) -> 1.84 | M7: 54 | N7: 1 | O7: =(($Q$3+1)*(M7/100))-1 -> 2.78 | P7: =($Q$3-O7) -> 3.22 | S7: 54 | T7: 1 | U7: =(($W$3+1)*(S7/100))-1 -> 3.32 | V7: =($W$3-U7) -> 3.68
A8: 56 | B8: 1 | C8: =(($E$3+1)*(A8/100))-1 -> 2.36 | D8: =($E$3-C8) -> 2.64 | G8: 56 | H8: 1 | I8: =(($K$3+1)*(G8/100))-1 -> 1.24 | J8: =($K$3-I8) -> 1.76 | M8: 56 | N8: 1 | O8: =(($Q$3+1)*(M8/100))-1 -> 2.92 | P8: =($Q$3-O8) -> 3.08 | S8: 56 | T8: 1 | U8: =(($W$3+1)*(S8/100))-1 -> 3.48 | V8: =($W$3-U8) -> 3.52
A9: 58 | B9: 1 | C9: =(($E$3+1)*(A9/100))-1 -> 2.48 | D9: =($E$3-C9) -> 2.52 | E9: Total de materiais (kg) | G9: 58 | H9: 1 | I9: =(($K$3+1)*(G9/100))-1 -> 1.32 | J9: =($K$3-I9) -> 1.68 | K9: Total de materiais (kg) | M9: 58 | N9: 1 | O9: =(($Q$3+1)*(M9/100))-1 -> 3.06 | P9: =($Q$3-O9) -> 2.94 | Q9: Total de materiais (kg) | S9: 58 | T9: 1 | U9: =(($W$3+1)*(S9/100))-1 -> 3.64 | V9: =($W$3-U9) -> 3.36 | W9: Total de materiais (kg)
A10: 60 | B10: 1 | C10: =(($E$3+1)*(A10/100))-1 -> 2.6 | D10: =($E$3-C10) -> 2.4 | G10: 60 | H10: 1 | I10: =(($K$3+1)*(G10/100))-1 -> 1.4 | J10: =($K$3-I10) -> 1.6 | M10: 60 | N10: 1 | O10: =(($Q$3+1)*(M10/100))-1 -> 3.2 | P10: =($Q$3-O10) -> 2.8 | S10: 60 | T10: 1 | U10: =(($W$3+1)*(S10/100))-1 -> 3.8 | V10: =($W$3-U10) -> 3.2
A12: =CONCATENATE("Traço massa acumulada (1:",E$3,")") -> Traço massa acumulada (1:5) | E12: 100 | G12: =CONCATENATE("Traço massa acumulada (1:",K$3,")") -> Traço massa acumulada (1:3) | K12: 100 | M12: =CONCATENATE("Traço massa acumulada (1:",Q$3,")") -> Traço massa acumulada (1:6) | Q12: 100 | S12: =CONCATENATE("Traço massa acumulada (1:",W$3,")") -> Traço massa acumulada (1:7) | W12: 100
A13: % argam | B13: Cim | C13: Areia | D13: Brita | E13: S (kg) | G13: % argam | H13: Cim | I13: Areia | J13: Brita | K13: S (kg) | M13: % argam | N13: Cim | O13: Areia | P13: Brita | Q13: S (kg) | S13: % argam | T13: Cim | U13: Areia | V13: Brita | W13: S (kg)
A14: =A5 -> 50 | B14: =E12/(E3+1) -> 16.666667 | C14: =B14*C5 -> 33.333333 | D14: =B14*D5 -> 50 | E14: =SUM(B14:D14) -> 100 | G14: =G5 -> 50 | H14: =K12/(K3+1) -> 25 | I14: =H14*I5 -> 25 | J14: =H14*J5 -> 50 | K14: =SUM(H14:J14) -> 100 | M14: =M5 -> 50 | N14: =Q12/(Q3+1) -> 14.285714 | O14: =N14*O5 -> 35.714286 | P14: =N14*P5 -> 50 | Q14: =SUM(N14:P14) -> 100 | S14: =S5 -> 50 | T14: =W12/(W3+1) -> 12.5 | U14: =T14*U5 -> 37.5 | V14: =T14*V5 -> 50 | W14: =SUM(T14:V14) -> 100
A15: =A6 -> 52 | B15: =D15/D6 -> 17.361111 | C15: =B15*C6 -> 36.805556 | D15: =D14 -> 50 | E15: =SUM(B15:D15) -> 104.16667 | G15: =G6 -> 52 | H15: =J15/J6 -> 26.041667 | I15: =H15*I6 -> 28.125 | J15: =J14 -> 50 | K15: =SUM(H15:J15) -> 104.16667 | M15: =M6 -> 52 | N15: =P15/P6 -> 14.880952 | O15: =N15*O6 -> 39.285714 | P15: =P14 -> 50 | Q15: =SUM(N15:P15) -> 104.16667 | S15: =S6 -> 52 | T15: =V15/V6 -> 13.020833 | U15: =T15*U6 -> 41.145833 | V15: =V14 -> 50 | W15: =SUM(T15:V15) -> 104.16667
A16: =A7 -> 54 | B16: =D16/D7 -> 18.115942 | C16: =B16*C7 -> 40.57971 | D16: =D15 -> 50 | E16: =SUM(B16:D16) -> 108.69565 | G16: =G7 -> 54 | H16: =J16/J7 -> 27.173913 | I16: =H16*I7 -> 31.521739 | J16: =J15 -> 50 | K16: =SUM(H16:J16) -> 108.69565 | M16: =M7 -> 54 | N16: =P16/P7 -> 15.52795 | O16: =N16*O7 -> 43.167702 | P16: =P15 -> 50 | Q16: =SUM(N16:P16) -> 108.69565 | S16: =S7 -> 54 | T16: =V16/V7 -> 13.586957 | U16: =T16*U7 -> 45.108696 | V16: =V15 -> 50 | W16: =SUM(T16:V16) -> 108.69565
A17: =A8 -> 56 | B17: =D17/D8 -> 18.939394 | C17: =B17*C8 -> 44.69697 | D17: =D16 -> 50 | E17: =SUM(B17:D17) -> 113.63636 | G17: =G8 -> 56 | H17: =J17/J8 -> 28.409091 | I17: =H17*I8 -> 35.227273 | J17: =J16 -> 50 | K17: =SUM(H17:J17) -> 113.63636 | M17: =M8 -> 56 | N17: =P17/P8 -> 16.233766 | O17: =N17*O8 -> 47.402597 | P17: =P16 -> 50 | Q17: =SUM(N17:P17) -> 113.63636 | S17: =S8 -> 56 | T17: =V17/V8 -> 14.204545 | U17: =T17*U8 -> 49.431818 | V17: =V16 -> 50 | W17: =SUM(T17:V17) -> 113.63636
A18: =A9 -> 58 | B18: =D18/D9 -> 19.84127 | C18: =B18*C9 -> 49.206349 | D18: =D17 -> 50 | E18: =SUM(B18:D18) -> 119.04762 | G18: =G9 -> 58 | H18: =J18/J9 -> 29.761905 | I18: =H18*I9 -> 39.285714 | J18: =J17 -> 50 | K18: =SUM(H18:J18) -> 119.04762 | M18: =M9 -> 58 | N18: =P18/P9 -> 17.006803 | O18: =N18*O9 -> 52.040816 | P18: =P17 -> 50 | Q18: =SUM(N18:P18) -> 119.04762 | S18: =S9 -> 58 | T18: =V18/V9 -> 14.880952 | U18: =T18*U9 -> 54.166667 | V18: =V17 -> 50 | W18: =SUM(T18:V18) -> 119.04762
A19: =A10 -> 60 | B19: =D19/D10 -> 20.833333 | C19: =B19*C10 -> 54.166667 | D19: =D18 -> 50 | E19: =SUM(B19:D19) -> 125 | G19: =G10 -> 60 | H19: =J19/J10 -> 31.25 | I19: =H19*I10 -> 43.75 | J19: =J18 -> 50 | K19: =SUM(H19:J19) -> 125 | M19: =M10 -> 60 | N19: =P19/P10 -> 17.857143 | O19: =N19*O10 -> 57.142857 | P19: =P18 -> 50 | Q19: =SUM(N19:P19) -> 125 | S19: =S10 -> 60 | T19: =V19/V10 -> 15.625 | U19: =T19*U10 -> 59.375 | V19: =V18 -> 50 | W19: =SUM(T19:V19) -> 125
A21: =CONCATENATE("Traço massa descontada (1:",E$3,")") -> Traço massa descontada (1:5) | G21: =CONCATENATE("Traço massa descontada (1:",K$3,")") -> Traço massa descontada (1:3) | M21: =CONCATENATE("Traço massa descontada (1:",Q$3,")") -> Traço massa descontada (1:6) | S21: =CONCATENATE("Traço massa descontada (1:",W$3,")") -> Traço massa descontada (1:7)
A22: % argam | B22: Cim | C22: Areia | D22: Brita | G22: % argam | H22: Cim | I22: Areia | J22: Brita | M22: % argam | N22: Cim | O22: Areia | P22: Brita | S22: % argam | T22: Cim | U22: Areia | V22: Brita
A23: =A5 -> 50 | B23: =B14 -> 16.666667 | C23: =C14 -> 33.333333 | D23: =D14 -> 50 | G23: =G5 -> 50 | H23: =H14 -> 25 | I23: =I14 -> 25 | J23: =J14 -> 50 | M23: =M5 -> 50 | N23: =N14 -> 14.285714 | O23: =O14 -> 35.714286 | P23: =P14 -> 50 | S23: =S5 -> 50 | T23: =T14 -> 12.5 | U23: =U14 -> 37.5 | V23: =V14 -> 50
A24: =A6 -> 52 | B24: =B15-B14 -> 0.69444444 | C24: =C15-C14 -> 3.4722222 | D24: =D15-D14 -> 0 | G24: =G6 -> 52 | H24: =H15-H14 -> 1.0416667 | I24: =I15-I14 -> 3.125 | J24: =J15-J14 -> 0 | M24: =M6 -> 52 | N24: =N15-N14 -> 0.5952381 | O24: =O15-O14 -> 3.5714286 | P24: =P15-P14 -> 0 | S24: =S6 -> 52 | T24: =T15-T14 -> 0.52083333 | U24: =U15-U14 -> 3.6458333 | V24: =V15-V14 -> 0
A25: =A7 -> 54 | B25: =B16-B15 -> 0.75483092 | C25: =C16-C15 -> 3.7741546 | D25: =D16-D15 -> 0 | G25: =G7 -> 54 | H25: =H16-H15 -> 1.1322464 | I25: =I16-I15 -> 3.3967391 | J25: =J16-J15 -> 0 | M25: =M7 -> 54 | N25: =N16-N15 -> 0.64699793 | O25: =O16-O15 -> 3.8819876 | P25: =P16-P15 -> 0 | S25: =S7 -> 54 | T25: =T16-T15 -> 0.56612319 | U25: =U16-U15 -> 3.9628623 | V25: =V16-V15 -> 0
A26: =A8 -> 56 | B26: =B17-B16 -> 0.82345191 | C26: =C17-C16 -> 4.1172596 | D26: =D17-D16 -> 0 | G26: =G8 -> 56 | H26: =H17-H16 -> 1.2351779 | I26: =I17-I16 -> 3.7055336 | J26: =J17-J16 -> 0 | M26: =M8 -> 56 | N26: =N17-N16 -> 0.70581592 | O26: =O17-O16 -> 4.2348955 | P26: =P17-P16 -> 0 | S26: =S8 -> 56 | T26: =T17-T16 -> 0.61758893 | U26: =U17-U16 -> 4.3231225 | V26: =V17-V16 -> 0
A27: =A9 -> 58 | B27: =B18-B17 -> 0.9018759 | C27: =C18-C17 -> 4.5093795 | D27: =D18-D17 -> 0 | G27: =G9 -> 58 | H27: =H18-H17 -> 1.3528139 | I27: =I18-I17 -> 4.0584416 | J27: =J18-J17 -> 0 | M27: =M9 -> 58 | N27: =N18-N17 -> 0.77303649 | O27: =O18-O17 -> 4.6382189 | P27: =P18-P17 -> 0 | S27: =S9 -> 58 | T27: =T18-T17 -> 0.67640693 | U27: =U18-U17 -> 4.7348485 | V27: =V18-V17 -> 0
A28: =A10 -> 60 | B28: =B19-B18 -> 0.99206349 | C28: =C19-C18 -> 4.9603175 | D28: =D19-D18 -> 0 | G28: =G10 -> 60 | H28: =H19-H18 -> 1.4880952 | I28: =I19-I18 -> 4.4642857 | J28: =J19-J18 -> 0 | M28: =M10 -> 60 | N28: =N19-N18 -> 0.85034014 | O28: =O19-O18 -> 5.1020408 | P28: =P19-P18 -> 0 | S28: =S10 -> 60 | T28: =T19-T18 -> 0.74404762 | U28: =U19-U18 -> 5.2083333 | V28: =V19-V18 -> 0

Sheet 3 traços
A2: FAMÍLIA CONCRETO
A3: Traço | B3: Família | C3: Traço | K3: a (%) | M3: 54
C4: Cimento | D4: Areia Fina | E4: Areia Média | F4: Areia Grossa | G4: Brita 0 | H4: Brita 1 | I4: Brita 2
A5: Rico | B5: =Traços!K3 -> 3 | C5: 1 | D5: =IFERROR(INDEX(Empacotamento!$U$7:$Z$7,1,MATCH(D$4,Empacotamento!$U2:$Z$2,0))*((($M$3/100)*(1+B5))-1),"") -> 0.17102838 | E5: =IFERROR(INDEX(Empacotamento!$U$7:$Z$7,1,MATCH(E$4,Empacotamento!$U2:$Z$2,0))*((($M$3/100)*(1+$B$5))-1),"") -> 0.5387394 | F5: =IFERROR(INDEX(Empacotamento!$U$7:$Z$7,1,MATCH(F$4,Empacotamento!$U2:$Z$2,0))*((($M$3/100)*(1+$B$5))-1),"") -> 0.45023222 | G5: =IFERROR(INDEX(Empacotamento!$U$7:$Z$7,1,MATCH('3 traços'!G$4,Empacotamento!$U2:$Z$2,0))*(B5-SUM(D5:F5)),"") -> 1.472 | H5: =IFERROR(INDEX(Empacotamento!$U$7:$Z$7,1,MATCH('3 traços'!H$4,Empacotamento!$U2:$Z$2,0))*(B5-SUM(D5:F5)),"") -> 0.1104 | I5: =IFERROR(INDEX(Empacotamento!$U$7:$Z$7,1,MATCH('3 traços'!I$4,Empacotamento!$U2:$Z$2,0))*($B$5-SUM(D5:F5)),"") -> 0.2576 | K5: Teor de Aditivo (%) | M5: 0.4
A6: Interm | B6: =Traços!E3 -> 5 | C6: 1 | D6: =IFERROR(INDEX(Empacotamento!$U$7:$Z$7,1,MATCH(D$4,Empacotamento!$U$2:$Z$2,0))*((($M$3/100)*(1+B6))-1),"") -> 0.3302617 | E6: =IFERROR(INDEX(Empacotamento!$U$7:$Z$7,1,MATCH(E$4,Empacotamento!$U$2:$Z$2,0))*((($M$3/100)*(1+B6))-1),"") -> 1.0403244 | F6: =IFERROR(INDEX(Empacotamento!$U$7:$Z$7,1,MATCH(F$4,Empacotamento!$U$2:$Z$2,0))*((($M$3/100)*(1+B6))-1),"") -> 0.86941393 | G6: =IFERROR(INDEX(Empacotamento!$U$7:$Z$7,1,MATCH('3 traços'!G$4,Empacotamento!$U$2:$Z$2,0))*(B6-SUM(D6:F6)),"") -> 2.208 | H6: =IFERROR(INDEX(Empacotamento!$U$7:$Z$7,1,MATCH('3 traços'!H$4,Empacotamento!$U$2:$Z$2,0))*(B6-SUM(D6:F6)),"") -> 0.1656 | I6: =IFERROR(INDEX(Empacotamento!$U$7:$Z$7,1,MATCH('3 traços'!I$4,Empacotamento!$U$2:$Z$2,0))*(B6-SUM(D6:F6)),"") -> 0.3864
A7: Pobre | B7: =Traços!W3 -> 7 | C7: 1 | D7: =IFERROR(INDEX(Empacotamento!$U$7:$Z$7,1,MATCH(D$4,Empacotamento!$U$2:$Z2,0))*((($M$3/100)*(1+B7))-1),"") -> 0.48949502 | E7: =IFERROR(INDEX(Empacotamento!$U$7:$Z$7,1,MATCH(E$4,Empacotamento!$U$2:$Z2,0))*((($M$3/100)*(1+B7))-1),"") -> 1.5419093 | F7: =IFERROR(INDEX(Empacotamento!$U$7:$Z$7,1,MATCH(F$4,Empacotamento!$U$2:$Z$2,0))*((($M$3/100)*(1+B7))-1),"") -> 1.2885957 | G7: =IFERROR(INDEX(Empacotamento!$U$7:$Z$7,1,MATCH('3 traços'!G$4,Empacotamento!$U$2:$Z$2,0))*(B7-SUM(D7:F7)),"") -> 2.944 | H7: =IFERROR(INDEX(Empacotamento!$U$7:$Z$7,1,MATCH('3 traços'!H$4,Empacotamento!$U$2:$Z$2,0))*(B7-SUM(D7:F7)),"") -> 0.2208 | I7: =IFERROR(INDEX(Empacotamento!$U$7:$Z$7,1,MATCH('3 traços'!I$4,Empacotamento!$U$2:$Z$2,0))*(B7-SUM(D7:F7)),"") -> 0.5152
A9: Traço | B9: g | C9: Cimento (kg/m3) | D9: A Fina (kg/m3) | E9: A Média (kg/m3) | F9: A Grossa (kg/m3) | G9: Brita 0 (kg/m3) | H9: Brita 1 (kg/m3) | I9: Brita 2 (kg/m3) | J9: Água (kg/m3) | K9: Aditivo 1 (kg/m3) | L9: a/c | M9: H
A11: Rico | B11: =G16 -> 2419.2265 | C11: =B11/(1+B5+L11) -> 543.6464 | D11: =IFERROR(C11*D5,"") -> 92.978964 | E11: =IFERROR(C11*E5,"") -> 292.88374 | F11: =IFERROR(C11*F5,"") -> 244.76712 | G11: =IFERROR(C11*G5,"") -> 800.2475 | H11: =IFERROR(C11*H5,"") -> 60.018563 | I11: =IFERROR(C11*I5,"") -> 140.04331 | J11: =L11*C11 -> 244.64088 | K11: =C11*$M$5/100 -> 2.1745856 | L11: 0.45 | M11: =(L11*100)/(1+B5) -> 11.25
A12: Interm | B12: =G21 -> 2435.1424 | C12: =B12/(1+B6+L12) -> 370.64573 | D12: =IFERROR(C12*D6,"") -> 122.41009 | E12: =IFERROR(C12*E6,"") -> 385.59178 | F12: =IFERROR(C12*F6,"") -> 322.24456 | G12: =IFERROR(C12*G6,"") -> 818.38577 | H12: =IFERROR(C12*H6,"") -> 61.378933 | I12: =IFERROR(C12*I6,"") -> 143.21751 | J12: =L12*C12 -> 211.26807 | K12: =C12*$M$5/100 -> 1.4825829 | L12: 0.57 | M12: =(L12*100)/(1+B6) -> 9.5
A13: Pobre | B13: =G26 -> 2419.2265 | C13: =B13/(1+B7+L13) -> 278.71273 | D13: =IFERROR(C13*D7,"") -> 136.42849 | E13: =IFERROR(C13*E7,"") -> 429.74976 | F13: =IFERROR(C13*F7,"") -> 359.14801 | G13: =IFERROR(C13*G7,"") -> 820.53027 | H13: =IFERROR(C13*H7,"") -> 61.53977 | I13: =IFERROR(C13*I7,"") -> 143.5928 | J13: =L13*C13 -> 189.52466 | K13: =C13*$M$5/100 -> 1.1148509 | L13: 0.68 | M13: =(L13*100)/(1+B7) -> 8.5
B15: =A5 -> Rico | C15: =B5 -> 3 | D15: Pvazio | E15: 1.9 | F15: Mesp1 | G15: g
D16: Pcheio | E16: 5.5 | F16: =((E16-E15)*4)/(3.1415*100*20/1000000) -> 2291.8988 | G16: =(F16+F18)/2 -> 2419.2265
D17: Pvazio | E17: 2.1 | F17: Mesp2
D18: Pcheio | E18: 6.1 | F18: =((E18-E17)*4)/(3.1415*100*20/1000000) -> 2546.5542
B20: =A6 -> Interm | C20: =B6 -> 5 | D20: Pvazio | E20: 1.9 | F20: Mesp1 | G20: g
D21: Pcheio | E21: 5.7 | F21: =((E21-E20)*4)/(3.1415*100*20/1000000) -> 2419.2265 | G21: =(F21+F23)/2 -> 2435.1424
D22: Pvazio | E22: 2.1 | F22: Mesp2
D23: Pcheio | E23: 5.95 | F23: =((E23-E22)*4)/(3.1415*100*20/1000000) -> 2451.0584
B25: =A7 -> Pobre | C25: =B7 -> 7 | D25: Pvazio | E25: 1.9 | F25: Mesp1 | G25: g
D26: Pcheio | E26: 5.65 | F26: =((E26-E25)*4)/(3.1415*100*20/1000000) -> 2387.3946 | G26: =(F26+F28)/2 -> 2419.2265
D27: Pvazio | E27: 2.1 | F27: Mesp2
D28: Pcheio | E28: 5.95 | F28: =((E28-E27)*4)/(3.1415*100*20/1000000) -> 2451.0584

Sheet Curvas dosagem (3t)
A2: CONCRETO CONVENCIONAL - 28 DIAS
A3: Equação de Abrams
D4: 28 dias | F4: 7 dia | H4: a/c | J4: m | L4: C | N4: Log fc7 | O4: Log fc28 | P4: 1/C
A5: fcj= A/Ba/c | D5: fcj1 | E5: 57 | F5: fcj1 | G5: 30 | H5: a/c1 | I5: ='3 traços'!L11 -> 0.45 | J5: m1 | K5: ='3 traços'!B5 -> 3 | L5: c1 | M5: ='3 traços'!C11 -> 543.6464 | N5: =LOG(G5) -> 1.4771213 | O5: =LOG(E5) -> 1.7558749 | P5: =1/M5 -> 0.0018394309
A6: log.fcj = log.A - a/c.log.B | D6: fcj2 | E6: 36 | F6: fcj2 | G6: 20 | H6: a/c2 | I6: ='3 traços'!L12 -> 0.57 | J6: m2 | K6: ='3 traços'!B6 -> 5 | L6: c2 | M6: ='3 traços'!C12 -> 370.64573 | N6: =LOG(G6) -> 1.30103 | O6: =LOG(E6) -> 1.5563025 | P6: =1/M6 -> 0.0026979941
A7: Onde: | D7: fcj3 | E7: 15 | F7: fcj3 | G7: 10 | H7: a/c3 | I7: ='3 traços'!L13 -> 0.68 | J7: m3 | K7: ='3 traços'!B7 -> 7 | L7: c3 | M7: ='3 traços'!C13 -> 278.71273 | N7: =LOG(G7) -> 1 | O7: =LOG(E7) -> 1.1760913 | P7: =1/M7 -> 0.0035879237
A8: y = log.fcj
A9: x = a/c
A11: Logo:
A12: y = a - x.b
A14: a | B14: =SLOPE($O$5:$O$7,$I$5:$I$7) -> -2.5078356
A15: b | B15: =INTERCEPT($O$5:$O$7,$I$5:$I$7) -> 2.9171964
A17: log fc1 | B17: a/c | C17: fc1
A18: =LOG(C18) -> 1.7558749 | B18: =((A18-$B$15)/$B$14) -> 0.46307721 | C18: =E5 -> 57
A19: =LOG(C19) -> 1.667453 | B19: =((A19-$B$15)/$B$14) -> 0.49833547 | C19: =(C18+C20)/2 -> 46.5
A20: =LOG(C20) -> 1.5563025 | B20: =((A20-$B$15)/$B$14) -> 0.54265673 | C20: =E6 -> 36
A21: =LOG(C21) -> 1.4065402 | B21: =((A21-$B$15)/$B$14) -> 0.60237449 | C21: =(C20+C22)/2 -> 25.5
A22: =LOG(C22) -> 1.1760913 | B22: =((A22-$B$15)/$B$14) -> 0.69426605 | C22: =E7 -> 15
A26: Equação de Lyse
A28: m = A + B*a/c
A29: Onde:
A30: x = a/c | B30: y = m
A31: Logo:
A32: y = A + B*x
A34: a | B34: =SLOPE($K$5:$K$7,$I$5:$I$7) -> 17.380353
A35: b | B35: =INTERCEPT($K$5:$K$7,$I$5:$I$7) -> -4.8488665
A37: x = a/c | B37: y = m
A38: =B18 -> 0.46307721 | B38: =$B$34*A38+$B$35 -> 3.1995788
A39: =B19 -> 0.49833547 | B39: =$B$34*A39+$B$35 -> 3.8123797
A40: =B20 -> 0.54265673 | B40: =$B$34*A40+$B$35 -> 4.5826989
A41: =B21 -> 0.60237449 | B41: =$B$34*A41+$B$35 -> 5.6206146
A42: =B22 -> 0.69426605 | B42: =$B$34*A42+$B$35 -> 7.2177223
A44: Equação de Molinari
A46: 1/C = A + B*m
A48: Onde:
A49: x = 1/C | B49: y = m
A50: Logo:
A51: x = A + B*y
A53: a | B53: =SLOPE($K$5:$K$7,$P$5:$P$7) -> 2287.4392
A54: b | B54: =INTERCEPT($K$5:$K$7,$P$5:$P$7) -> -1.1954138
...

Sheet Cálculo dos traços (3t)
A2: REFERÊNCIA 28dd - CÁLCULO DOS TRAÇOS E CUSTOS - por metro cúbico
A3: fc1 | B3: a/c | C3: m | D3: Cimento | E3: Areia Fina | F3: Areia Média | G3: Areia Grossa | H3: Brita 0 | I3: Brita 1 | J3: Brita 2 | K3: Aditivo | L3: Água
D4: (kg) | E4: (kg) | F4: (kg) | G4: (kg) | H4: (kg) | I4: (kg) | J4: (kg) | K4: (kg) | L4: (kg)
